Workbook
Name SiteName: Setup!$B$3
Name Place: Setup!$B$4
Name Variety: Setup!$B$7
Name SowDate: Setup!$B$8
Name SeedAge: Setup!$B$9
Name TransDate: Setup!$B$10
Name Day_0: Setup!$B$11
Name DataStart: Setup!$B$13
Name FP_TP: Setup!$D$16
Name FP_b: Setup!$E$16
Name MD_TP: Setup!$D$17
Name MD_b: Setup!$E$17
Name FP_m2: Setup!$F$16
Name MD_m2: Setup!$F$17
Name TPDate: Setup!$B$18
Name cfg_0: Setup!$B$22
Name cfg_1: Setup!$B$23
Name cfg_2: Setup!$B$24
Name cfg_3: Setup!$B$25
Name cfg_4: Setup!$B$26
Name cfg_5: Setup!$B$27
Name cfg_6: Setup!$B$28
Name cfg_7: Setup!$B$29
Name cfg_8: Setup!$B$30
Name cfg_9: Setup!$B$31
Name cfg_10: Setup!$B$32
Name cfg_11: Setup!$B$33
Name cfg_12: Setup!$B$34
Name cfg_13: Setup!$B$35
Name PitanS: Schedule_Farmer!$J$11
Name PitanE: Schedule_Farmer!$K$11
Name MDS: Schedule_Farmer!$J$13
Name MDE: Schedule_Farmer!$K$13
Name FloodS: Schedule_Farmer!$J$15
Name FloodE: Schedule_Farmer!$K$15
Name C1S: Schedule_Farmer!$J$16
Name C3E: Schedule_Farmer!$J$23
Name HeadD: Schedule_Farmer!$J$19
Name HarvD: Schedule_Farmer!$J$25

Sheet Today
A1: =IF(SiteName="","3F4D Water Monitor",SiteName&IF(Place="",""," - "&Place))
A3: Today / আজ | B3: =TODAY()
A4: Days after transplanting | B4: =IF(ISNUMBER(TransDate),TODAY()-TransDate,"")
A5: Today's water level / আজকের পানির স্তর | B5: =IF(ISNA(MATCH(TODAY(),Data_Farmer!$D$1:$FQ$1,0)),"(today is not in Data_Farmer)",IF(AND(ISNUMBER(INDEX(Data_Farmer!$D$12:$FQ$12,MATCH(TODAY(),Data_Farmer!$D$1:$FQ$1,0))),ISNUMBER(INDEX(Data_Farmer!$D$37:$FQ$37,MATCH(TODAY(),Data_Farmer!$D$1:$FQ$1,0)))),"Entered","NOT YET ENTERED"))
A6: Last entry | B6: =IF(_xlfn.MAXIFS(Data_Farmer!$D$1:$FQ$1,Data_Farmer!$D$33:$FQ$33,1)=0,"",_xlfn.MAXIFS(Data_Farmer!$D$1:$FQ$1,Data_Farmer!$D$33:$FQ$33,1))
A7: Days without entry | B7: =IF(B6="","",MAX(0,TODAY()-B6-1))
A8: Stage today | B8: =IFERROR(INDEX(Data_Farmer!$D$6:$FQ$6,MATCH(TODAY(),Data_Farmer!$D$1:$FQ$1,0)),"")
B10: FP | C10: 3F4D+MD
A11: Latest water level - date | B11: =IF(_xlfn.MAXIFS(Data_Farmer!$D$1:$FQ$1,Data_Farmer!$D$33:$FQ$33,1)=0,"",_xlfn.MAXIFS(Data_Farmer!$D$1:$FQ$1,Data_Farmer!$D$33:$FQ$33,1)) | C11: =IF(_xlfn.MAXIFS(Data_Farmer!$D$1:$FQ$1,Data_Farmer!$D$58:$FQ$58,1)=0,"",_xlfn.MAXIFS(Data_Farmer!$D$1:$FQ$1,Data_Farmer!$D$58:$FQ$58,1))
A12: Water level (cm, after irrigation if irrigated) | B12: =IF(B11="","",INDEX(Data_Farmer!$D$32:$FQ$32,MATCH(B11,Data_Farmer!$D$1:$FQ$1,0))) | C12: =IF(C11="","",INDEX(Data_Farmer!$D$57:$FQ$57,MATCH(C11,Data_Farmer!$D$1:$FQ$1,0)))
A13: State | B13: =IF(B12="","",IF(B12>0,"water above the soil surface",IF(B12<0,"water below the soil surface","at the soil surface"))) | C13: =IF(C12="","",IF(C12>0,"water above the soil surface",IF(C12<0,"water below the soil surface","at the soil surface")))
A14: Total irrigation (mm) | B14: =ROUND(SUM(Data_Farmer!$D$21:$FQ$21),0) | C14: =ROUND(SUM(Data_Farmer!$D$46:$FQ$46),0)
A15: Number of irrigations | B15: =COUNT(Data_Farmer!$D$21:$FQ$21) | C15: =COUNT(Data_Farmer!$D$46:$FQ$46)
A16: Water saving by 3F4D+MD | B16: =IF(B14=0,"",B14-C14&" mm") | C16: =IF(B14=0,"",ROUND(100*(B14-C14)/B14,0)&" %")
A17: Farmer working time (min) | B17: =SUM(Data_Farmer!$D$26:$FQ$26) | C17: =SUM(Data_Farmer!$D$51:$FQ$51)
A18: Labour (BDT) | B18: =SUM(Data_Farmer!$D$28:$FQ$28) | C18: =SUM(Data_Farmer!$D$53:$FQ$53)
A19: N applied (kg/10a) | B19: =Other_info!AM5 | C19: =Other_info!AO5
A20: P applied (kg/10a) | B20: =Other_info!AN5 | C20: =Other_info!AP5
B22: Next events (schedule) | C22: Date
A23: Next 1 | B23: =IFERROR(INDEX(Schedule_Farmer!$A$5:$A$38,MATCH(SMALL(Schedule_Farmer!$L$5:$L$38,1),Schedule_Farmer!$L$5:$L$38,0))&" ("&INDEX(Schedule_Farmer!$C$5:$C$38,MATCH(SMALL(Schedule_Farmer!$L$5:$L$38,1),Schedule_Farmer!$L$5:$L$38,0))&")","") | C23: =IFERROR(INT(SMALL(Schedule_Farmer!$L$5:$L$38,1)),"") | D23: =IF(C23="","",IF(C23-TODAY()=0,"today","in "&(C23-TODAY())&" days"))
A24: Next 2 | B24: =IFERROR(INDEX(Schedule_Farmer!$A$5:$A$38,MATCH(SMALL(Schedule_Farmer!$L$5:$L$38,2),Schedule_Farmer!$L$5:$L$38,0))&" ("&INDEX(Schedule_Farmer!$C$5:$C$38,MATCH(SMALL(Schedule_Farmer!$L$5:$L$38,2),Schedule_Farmer!$L$5:$L$38,0))&")","") | C24: =IFERROR(INT(SMALL(Schedule_Farmer!$L$5:$L$38,2)),"") | D24: =IF(C24="","",IF(C24-TODAY()=0,"today","in "&(C24-TODAY())&" days"))
A25: Next 3 | B25: =IFERROR(INDEX(Schedule_Farmer!$A$5:$A$38,MATCH(SMALL(Schedule_Farmer!$L$5:$L$38,3),Schedule_Farmer!$L$5:$L$38,0))&" ("&INDEX(Schedule_Farmer!$C$5:$C$38,MATCH(SMALL(Schedule_Farmer!$L$5:$L$38,3),Schedule_Farmer!$L$5:$L$38,0))&")","") | C25: =IFERROR(INT(SMALL(Schedule_Farmer!$L$5:$L$38,3)),"") | D25: =IF(C25="","",IF(C25-TODAY()=0,"today","in "&(C25-TODAY())&" days"))
A26: Next 4 | B26: =IFERROR(INDEX(Schedule_Farmer!$A$5:$A$38,MATCH(SMALL(Schedule_Farmer!$L$5:$L$38,4),Schedule_Farmer!$L$5:$L$38,0))&" ("&INDEX(Schedule_Farmer!$C$5:$C$38,MATCH(SMALL(Schedule_Farmer!$L$5:$L$38,4),Schedule_Farmer!$L$5:$L$38,0))&")","") | C26: =IFERROR(INT(SMALL(Schedule_Farmer!$L$5:$L$38,4)),"") | D26: =IF(C26="","",IF(C26-TODAY()=0,"today","in "&(C26-TODAY())&" days"))
A28: Actual date not entered (overdue events) | B28: =COUNTIF(Schedule_Farmer!$H$5:$H$38,"OVERDUE")

Sheet Calendar
A1: Calendar / ক্যালেন্ডার
A2: =IF(SiteName="","",SiteName&IF(Place="",""," - "&Place)) | F2: =IF(Variety="","","Variety: "&Variety)
B4: 3F4D+MD activities | C4: Planned | D4: Actual | G4: FP activities | H4: Planned | I4: Actual
A5: 01. | B5: =Schedule_Farmer!A5&IF(Schedule_Farmer!E5<>Schedule_Farmer!D5," (to "&TEXT(Schedule_Farmer!E5,"dd mmm")&")","") | C5: =IF(Schedule_Farmer!D5="","",Schedule_Farmer!D5) | D5: =IF(Schedule_Farmer!F5="","",Schedule_Farmer!F5) | F5: 01. | G5: =Schedule_Farmer!A28&IF(Schedule_Farmer!E28<>Schedule_Farmer!D28," (to "&TEXT(Schedule_Farmer!E28,"dd mmm")&")","") | H5: =IF(Schedule_Farmer!D28="","",Schedule_Farmer!D28) | I5: =IF(Schedule_Farmer!F28="","",Schedule_Farmer!F28)
A6: 02. | B6: =Schedule_Farmer!A6&IF(Schedule_Farmer!E6<>Schedule_Farmer!D6," (to "&TEXT(Schedule_Farmer!E6,"dd mmm")&")","") | C6: =IF(Schedule_Farmer!D6="","",Schedule_Farmer!D6) | D6: =IF(Schedule_Farmer!F6="","",Schedule_Farmer!F6) | F6: 02. | G6: =Schedule_Farmer!A29&IF(Schedule_Farmer!E29<>Schedule_Farmer!D29," (to "&TEXT(Schedule_Farmer!E29,"dd mmm")&")","") | H6: =IF(Schedule_Farmer!D29="","",Schedule_Farmer!D29) | I6: =IF(Schedule_Farmer!F29="","",Schedule_Farmer!F29)
A7: 03. | B7: =Schedule_Farmer!A7&IF(Schedule_Farmer!E7<>Schedule_Farmer!D7," (to "&TEXT(Schedule_Farmer!E7,"dd mmm")&")","") | C7: =IF(Schedule_Farmer!D7="","",Schedule_Farmer!D7) | D7: =IF(Schedule_Farmer!F7="","",Schedule_Farmer!F7) | F7: 03. | G7: =Schedule_Farmer!A30&IF(Schedule_Farmer!E30<>Schedule_Farmer!D30," (to "&TEXT(Schedule_Farmer!E30,"dd mmm")&")","") | H7: =IF(Schedule_Farmer!D30="","",Schedule_Farmer!D30) | I7: =IF(Schedule_Farmer!F30="","",Schedule_Farmer!F30)
A8: 04. | B8: =Schedule_Farmer!A8&IF(Schedule_Farmer!E8<>Schedule_Farmer!D8," (to "&TEXT(Schedule_Farmer!E8,"dd mmm")&")","") | C8: =IF(Schedule_Farmer!D8="","",Schedule_Farmer!D8) | D8: =IF(Schedule_Farmer!F8="","",Schedule_Farmer!F8) | F8: 04. | G8: =Schedule_Farmer!A31&IF(Schedule_Farmer!E31<>Schedule_Farmer!D31," (to "&TEXT(Schedule_Farmer!E31,"dd mmm")&")","") | H8: =IF(Schedule_Farmer!D31="","",Schedule_Farmer!D31) | I8: =IF(Schedule_Farmer!F31="","",Schedule_Farmer!F31)
A9: 05. | B9: =Schedule_Farmer!A9&IF(Schedule_Farmer!E9<>Schedule_Farmer!D9," (to "&TEXT(Schedule_Farmer!E9,"dd mmm")&")","") | C9: =IF(Schedule_Farmer!D9="","",Schedule_Farmer!D9) | D9: =IF(Schedule_Farmer!F9="","",Schedule_Farmer!F9) | F9: 05. | G9: =Schedule_Farmer!A32&IF(Schedule_Farmer!E32<>Schedule_Farmer!D32," (to "&TEXT(Schedule_Farmer!E32,"dd mmm")&")","") | H9: =IF(Schedule_Farmer!D32="","",Schedule_Farmer!D32) | I9: =IF(Schedule_Farmer!F32="","",Schedule_Farmer!F32)
A10: 06. | B10: =Schedule_Farmer!A10&IF(Schedule_Farmer!E10<>Schedule_Farmer!D10," (to "&TEXT(Schedule_Farmer!E10,"dd mmm")&")","") | C10: =IF(Schedule_Farmer!D10="","",Schedule_Farmer!D10) | D10: =IF(Schedule_Farmer!F10="","",Schedule_Farmer!F10) | F10: 06. | G10: =Schedule_Farmer!A33&IF(Schedule_Farmer!E33<>Schedule_Farmer!D33," (to "&TEXT(Schedule_Farmer!E33,"dd mmm")&")","") | H10: =IF(Schedule_Farmer!D33="","",Schedule_Farmer!D33) | I10: =IF(Schedule_Farmer!F33="","",Schedule_Farmer!F33)
A11: 07. | B11: =Schedule_Farmer!A11&IF(Schedule_Farmer!E11<>Schedule_Farmer!D11," (to "&TEXT(Schedule_Farmer!E11,"dd mmm")&")","") | C11: =IF(Schedule_Farmer!D11="","",Schedule_Farmer!D11) | D11: =IF(Schedule_Farmer!F11="","",Schedule_Farmer!F11) | F11: 07. | G11: =Schedule_Farmer!A34&IF(Schedule_Farmer!E34<>Schedule_Farmer!D34," (to "&TEXT(Schedule_Farmer!E34,"dd mmm")&")","") | H11: =IF(Schedule_Farmer!D34="","",Schedule_Farmer!D34) | I11: =IF(Schedule_Farmer!F34="","",Schedule_Farmer!F34)
A12: 08. | B12: =Schedule_Farmer!A12&IF(Schedule_Farmer!E12<>Schedule_Farmer!D12," (to "&TEXT(Schedule_Farmer!E12,"dd mmm")&")","") | C12: =IF(Schedule_Farmer!D12="","",Schedule_Farmer!D12) | D12: =IF(Schedule_Farmer!F12="","",Schedule_Farmer!F12) | F12: 08. | G12: =Schedule_Farmer!A35&IF(Schedule_Farmer!E35<>Schedule_Farmer!D35," (to "&TEXT(Schedule_Farmer!E35,"dd mmm")&")","") | H12: =IF(Schedule_Farmer!D35="","",Schedule_Farmer!D35) | I12: =IF(Schedule_Farmer!F35="","",Schedule_Farmer!F35)
A13: 09. | B13: =Schedule_Farmer!A13&IF(Schedule_Farmer!E13<>Schedule_Farmer!D13," (to "&TEXT(Schedule_Farmer!E13,"dd mmm")&")","") | C13: =IF(Schedule_Farmer!D13="","",Schedule_Farmer!D13) | D13: =IF(Schedule_Farmer!F13="","",Schedule_Farmer!F13) | F13: 09. | G13: =Schedule_Farmer!A36&IF(Schedule_Farmer!E36<>Schedule_Farmer!D36," (to "&TEXT(Schedule_Farmer!E36,"dd mmm")&")","") | H13: =IF(Schedule_Farmer!D36="","",Schedule_Farmer!D36) | I13: =IF(Schedule_Farmer!F36="","",Schedule_Farmer!F36)
A14: 10. | B14: =Schedule_Farmer!A14&IF(Schedule_Farmer!E14<>Schedule_Farmer!D14," (to "&TEXT(Schedule_Farmer!E14,"dd mmm")&")","") | C14: =IF(Schedule_Farmer!D14="","",Schedule_Farmer!D14) | D14: =IF(Schedule_Farmer!F14="","",Schedule_Farmer!F14) | F14: 10. | G14: =Schedule_Farmer!A37&IF(Schedule_Farmer!E37<>Schedule_Farmer!D37," (to "&TEXT(Schedule_Farmer!E37,"dd mmm")&")","") | H14: =IF(Schedule_Farmer!D37="","",Schedule_Farmer!D37) | I14: =IF(Schedule_Farmer!F37="","",Schedule_Farmer!F37)
A15: 11. | B15: =Schedule_Farmer!A15&IF(Schedule_Farmer!E15<>Schedule_Farmer!D15," (to "&TEXT(Schedule_Farmer!E15,"dd mmm")&")","") | C15: =IF(Schedule_Farmer!D15="","",Schedule_Farmer!D15) | D15: =IF(Schedule_Farmer!F15="","",Schedule_Farmer!F15) | F15: 11. | G15: =Schedule_Farmer!A38&IF(Schedule_Farmer!E38<>Schedule_Farmer!D38," (to "&TEXT(Schedule_Farmer!E38,"dd mmm")&")","") | H15: =IF(Schedule_Farmer!D38="","",Schedule_Farmer!D38) | I15: =IF(Schedule_Farmer!F38="","",Schedule_Farmer!F38)
A16: 12. | B16: =Schedule_Farmer!A16&IF(Schedule_Farmer!E16<>Schedule_Farmer!D16," (to "&TEXT(Schedule_Farmer!E16,"dd mmm")&")","") | C16: =IF(Schedule_Farmer!D16="","",Schedule_Farmer!D16) | D16: =IF(Schedule_Farmer!F16="","",Schedule_Farmer!F16)
A17: 13. | B17: =Schedule_Farmer!A17&IF(Schedule_Farmer!E17<>Schedule_Farmer!D17," (to "&TEXT(Schedule_Farmer!E17,"dd mmm")&")","") | C17: =IF(Schedule_Farmer!D17="","",Schedule_Farmer!D17) | D17: =IF(Schedule_Farmer!F17="","",Schedule_Farmer!F17)
A18: 14. | B18: =Schedule_Farmer!A18&IF(Schedule_Farmer!E18<>Schedule_Farmer!D18," (to "&TEXT(Schedule_Farmer!E18,"dd mmm")&")","") | C18: =IF(Schedule_Farmer!D18="","",Schedule_Farmer!D18) | D18: =IF(Schedule_Farmer!F18="","",Schedule_Farmer!F18)
A19: 15. | B19: =Schedule_Farmer!A19&IF(Schedule_Farmer!E19<>Schedule_Farmer!D19," (to "&TEXT(Schedule_Farmer!E19,"dd mmm")&")","") | C19: =IF(Schedule_Farmer!D19="","",Schedule_Farmer!D19) | D19: =IF(Schedule_Farmer!F19="","",Schedule_Farmer!F19)
A20: 16. | B20: =Schedule_Farmer!A20&IF(Schedule_Farmer!E20<>Schedule_Farmer!D20," (to "&TEXT(Schedule_Farmer!E20,"dd mmm")&")","") | C20: =IF(Schedule_Farmer!D20="","",Schedule_Farmer!D20) | D20: =IF(Schedule_Farmer!F20="","",Schedule_Farmer!F20)
A21: 17. | B21: =Schedule_Farmer!A21&IF(Schedule_Farmer!E21<>Schedule_Farmer!D21," (to "&TEXT(Schedule_Farmer!E21,"dd mmm")&")","") | C21: =IF(Schedule_Farmer!D21="","",Schedule_Farmer!D21) | D21: =IF(Schedule_Farmer!F21="","",Schedule_Farmer!F21)
A22: 18. | B22: =Schedule_Farmer!A22&IF(Schedule_Farmer!E22<>Schedule_Farmer!D22," (to "&TEXT(Schedule_Farmer!E22,"dd mmm")&")","") | C22: =IF(Schedule_Farmer!D22="","",Schedule_Farmer!D22) | D22: =IF(Schedule_Farmer!F22="","",Schedule_Farmer!F22)
A23: 19. | B23: =Schedule_Farmer!A23&IF(Schedule_Farmer!E23<>Schedule_Farmer!D23," (to "&TEXT(Schedule_Farmer!E23,"dd mmm")&")","") | C23: =IF(Schedule_Farmer!D23="","",Schedule_Farmer!D23) | D23: =IF(Schedule_Farmer!F23="","",Schedule_Farmer!F23)
A24: 20. | B24: =Schedule_Farmer!A24&IF(Schedule_Farmer!E24<>Schedule_Farmer!D24," (to "&TEXT(Schedule_Farmer!E24,"dd mmm")&")","") | C24: =IF(Schedule_Farmer!D24="","",Schedule_Farmer!D24) | D24: =IF(Schedule_Farmer!F24="","",Schedule_Farmer!F24)
A25: 21. | B25: =Schedule_Farmer!A25&IF(Schedule_Farmer!E25<>Schedule_Farmer!D25," (to "&TEXT(Schedule_Farmer!E25,"dd mmm")&")","") | C25: =IF(Schedule_Farmer!D25="","",Schedule_Farmer!D25) | D25: =IF(Schedule_Farmer!F25="","",Schedule_Farmer!F25)
A27: Pitan and the last irrigation are optional and may be carried out or omitted. Enter actual dates in Schedule_Farmer.
B29: Tiller (stem) number measurement | C29: Date
B30: Day 50 after sowing | C30: =IF(ISNUMBER(SowDate),SowDate+50,"")
B31: Day 60 after sowing | C31: =IF(ISNUMBER(SowDate),SowDate+60,"")
B32: Day 70 after sowing | C32: =IF(ISNUMBER(SowDate),SowDate+70,"")
B33: Day 80 after sowing | C33: =IF(ISNUMBER(SowDate),SowDate+80,"")
B34: Day 90 after sowing | C34: =IF(ISNUMBER(SowDate),SowDate+90,"")
B36: Water sampling: once a week

Sheet Data_Farmer
A1: =IF(SiteName="","3F4D Water Monitor",SiteName) | B1: Date / তারিখ | C1: Season | D1: =IF(ISNUMBER(DataStart),DataStart+0,"") | E1: =IF(ISNUMBER(DataStart),DataStart+1,"") | F1: =IF(ISNUMBER(DataStart),DataStart+2,"") | G1: =IF(ISNUMBER(DataStart),DataStart+3,"") | H1: =IF(ISNUMBER(DataStart),DataStart+4,"") | I1: =IF(ISNUMBER(DataStart),DataStart+5,"") | J1: =IF(ISNUMBER(DataStart),DataStart+6,"") | K1: =IF(ISNUMBER(DataStart),DataStart+7,"") | L1: =IF(ISNUMBER(DataStart),DataStart+8,"") | M1: =IF(ISNUMBER(DataStart),DataStart+9,"") | N1: =IF(ISNUMBER(DataStart),DataStart+10,"") | O1: =IF(ISNUMBER(DataStart),DataStart+11,"") | P1: =IF(ISNUMBER(DataStart),DataStart+12,"") | Q1: =IF(ISNUMBER(DataStart),DataStart+13,"") | R1: =IF(ISNUMBER(DataStart),DataStart+14,"") | S1: =IF(ISNUMBER(DataStart),DataStart+15,"") | T1: =IF(ISNUMBER(DataStart),DataStart+16,"") | U1: =IF(ISNUMBER(DataStart),DataStart+17,"") | V1: =IF(ISNUMBER(DataStart),DataStart+18,"") | W1: =IF(ISNUMBER(DataStart),DataStart+19,"") | X1: =IF(ISNUMBER(DataStart),DataStart+20,"") | Y1: =IF(ISNUMBER(DataStart),DataStart+21,"") | Z1: =IF(ISNUMBER(DataStart),DataStart+22,"") | AA1: =IF(ISNUMBER(DataStart),DataStart+23,"") | AB1: =IF(ISNUMBER(DataStart),DataStart+24,"") | AC1: =IF(ISNUMBER(DataStart),DataStart+25,"") | AD1: =IF(ISNUMBER(DataStart),DataStart+26,"") | AE1: =IF(ISNUMBER(DataStart),DataStart+27,"") | AF1: =IF(ISNUMBER(DataStart),DataStart+28,"") | AG1: =IF(ISNUMBER(DataStart),DataStart+29,"") | AH1: =IF(ISNUMBER(DataStart),DataStart+30,"") | AI1: =IF(ISNUMBER(DataStart),DataStart+31,"") | AJ1: =IF(ISNUMBER(DataStart),DataStart+32,"") | AK1: =IF(ISNUMBER(DataStart),DataStart+33,"") | AL1: =IF(ISNUMBER(DataStart),DataStart+34,"") | AM1: =IF(ISNUMBER(DataStart),DataStart+35,"") | AN1: =IF(ISNUMBER(DataStart),DataStart+36,"") | AO1: =IF(ISNUMBER(DataStart),DataStart+37,"") | AP1: =IF(ISNUMBER(DataStart),DataStart+38,"") | AQ1: =IF(ISNUMBER(DataStart),DataStart+39,"") | AR1: =IF(ISNUMBER(DataStart),DataStart+40,"") | AS1: =IF(ISNUMBER(DataStart),DataStart+41,"") | AT1: =IF(ISNUMBER(DataStart),DataStart+42,"") | AU1: =IF(ISNUMBER(DataStart),DataStart+43,"") | AV1: =IF(ISNUMBER(DataStart),DataStart+44,"") | AW1: =IF(ISNUMBER(DataStart),DataStart+45,"") | AX1: =IF(ISNUMBER(DataStart),DataStart+46,"") | AY1: =IF(ISNUMBER(DataStart),DataStart+47,"") | AZ1: =IF(ISNUMBER(DataStart),DataStart+48,"") | BA1: =IF(ISNUMBER(DataStart),DataStart+49,"") | BB1: =IF(ISNUMBER(DataStart),DataStart+50,"") | BC1: =IF(ISNUMBER(DataStart),DataStart+51,"") | BD1: =IF(ISNUMBER(DataStart),DataStart+52,"") | BE1: =IF(ISNUMBER(DataStart),DataStart+53,"") | BF1: =IF(ISNUMBER(DataStart),DataStart+54,"") | BG1: =IF(ISNUMBER(DataStart),DataStart+55,"") | BH1: =IF(ISNUMBER(DataStart),DataStart+56,"") | BI1: =IF(ISNUMBER(DataStart),DataStart+57,"") | BJ1: =IF(ISNUMBER(DataStart),DataStart+58,"") | BK1: =IF(ISNUMBER(DataStart),DataStart+59,"") | BL1: =IF(ISNUMBER(DataStart),DataStart+60,"") | BM1: =IF(ISNUMBER(DataStart),DataStart+61,"") | BN1: =IF(ISNUMBER(DataStart),DataStart+62,"") | BO1: =IF(ISNUMBER(DataStart),DataStart+63,"") | BP1: =IF(ISNUMBER(DataStart),DataStart+64,"") | BQ1: =IF(ISNUMBER(DataStart),DataStart+65,"") | BR1: =IF(ISNUMBER(DataStart),DataStart+66,"") | BS1: =IF(ISNUMBER(DataStart),DataStart+67,"") | BT1: =IF(ISNUMBER(DataStart),DataStart+68,"") | BU1: =IF(ISNUMBER(DataStart),DataStart+69,"") | BV1: =IF(ISNUMBER(DataStart),DataStart+70,"") | BW1: =IF(ISNUMBER(DataStart),DataStart+71,"") | BX1: =IF(ISNUMBER(DataStart),DataStart+72,"") | BY1: =IF(ISNUMBER(DataStart),DataStart+73,"") | BZ1: =IF(ISNUMBER(DataStart),DataStart+74,"") | CA1: =IF(ISNUMBER(DataStart),DataStart+75,"") | CB1: =IF(ISNUMBER(DataStart),DataStart+76,"") | CC1: =IF(ISNUMBER(DataStart),DataStart+77,"") | CD1: =IF(ISNUMBER(DataStart),DataStart+78,"") | CE1: =IF(ISNUMBER(DataStart),DataStart+79,"") | CF1: =IF(ISNUMBER(DataStart),DataStart+80,"") | CG1: =IF(ISNUMBER(DataStart),DataStart+81,"") | CH1: =IF(ISNUMBER(DataStart),DataStart+82,"") | CI1: =IF(ISNUMBER(DataStart),DataStart+83,"") | CJ1: =IF(ISNUMBER(DataStart),DataStart+84,"") | CK1: =IF(ISNUMBER(DataStart),DataStart+85,"") | CL1: =IF(ISNUMBER(DataStart),DataStart+86,"") | CM1: =IF(ISNUMBER(DataStart),DataStart+87,"") | CN1: =IF(ISNUMBER(DataStart),DataStart+88,"") | CO1: =IF(ISNUMBER(DataStart),DataStart+89,"") | CP1: =IF(ISNUMBER(DataStart),DataStart+90,"") | CQ1: =IF(ISNUMBER(DataStart),DataStart+91,"") | CR1: =IF(ISNUMBER(DataStart),DataStart+92,"") | CS1: =IF(ISNUMBER(DataStart),DataStart+93,"") | CT1: =IF(ISNUMBER(DataStart),DataStart+94,"") | CU1: =IF(ISNUMBER(DataStart),DataStart+95,"") | CV1: =IF(ISNUMBER(DataStart),DataStart+96,"") | CW1: =IF(ISNUMBER(DataStart),DataStart+97,"") | CX1: =IF(ISNUMBER(DataStart),DataStart+98,"") | CY1: =IF(ISNUMBER(DataStart),DataStart+99,"") | CZ1: =IF(ISNUMBER(DataStart),DataStart+100,"") | DA1: =IF(ISNUMBER(DataStart),DataStart+101,"") | DB1: =IF(ISNUMBER(DataStart),DataStart+102,"") | DC1: =IF(ISNUMBER(DataStart),DataStart+103,"") | DD1: =IF(ISNUMBER(DataStart),DataStart+104,"") | DE1: =IF(ISNUMBER(DataStart),DataStart+105,"") | DF1: =IF(ISNUMBER(DataStart),DataStart+106,"") | DG1: =IF(ISNUMBER(DataStart),DataStart+107,"") | DH1: =IF(ISNUMBER(DataStart),DataStart+108,"") | DI1: =IF(ISNUMBER(DataStart),DataStart+109,"") | DJ1: =IF(ISNUMBER(DataStart),DataStart+110,"") | DK1: =IF(ISNUMBER(DataStart),DataStart+111,"") | DL1: =IF(ISNUMBER(DataStart),DataStart+112,"") | DM1: =IF(ISNUMBER(DataStart),DataStart+113,"") | DN1: =IF(ISNUMBER(DataStart),DataStart+114,"") | DO1: =IF(ISNUMBER(DataStart),DataStart+115,"") | DP1: =IF(ISNUMBER(DataStart),DataStart+116,"") | DQ1: =IF(ISNUMBER(DataStart),DataStart+117,"") | DR1: =IF(ISNUMBER(DataStart),DataStart+118,"") | DS1: =IF(ISNUMBER(DataStart),DataStart+119,"") | DT1: =IF(ISNUMBER(DataStart),DataStart+120,"") | DU1: =IF(ISNUMBER(DataStart),DataStart+121,"") | DV1: =IF(ISNUMBER(DataStart),DataStart+122,"") | DW1: =IF(ISNUMBER(DataStart),DataStart+123,"") | DX1: =IF(ISNUMBER(DataStart),DataStart+124,"") | DY1: =IF(ISNUMBER(DataStart),DataStart+125,"") | DZ1: =IF(ISNUMBER(DataStart),DataStart+126,"") | EA1: =IF(ISNUMBER(DataStart),DataStart+127,"") | EB1: =IF(ISNUMBER(DataStart),DataStart+128,"") | EC1: =IF(ISNUMBER(DataStart),DataStart+129,"") | ED1: =IF(ISNUMBER(DataStart),DataStart+130,"") | EE1: =IF(ISNUMBER(DataStart),DataStart+131,"") | EF1: =IF(ISNUMBER(DataStart),DataStart+132,"") | EG1: =IF(ISNUMBER(DataStart),DataStart+133,"") | EH1: =IF(ISNUMBER(DataStart),DataStart+134,"") | EI1: =IF(ISNUMBER(DataStart),DataStart+135,"") | EJ1: =IF(ISNUMBER(DataStart),DataStart+136,"") | EK1: =IF(ISNUMBER(DataStart),DataStart+137,"") | EL1: =IF(ISNUMBER(DataStart),DataStart+138,"") | EM1: =IF(ISNUMBER(DataStart),DataStart+139,"") | EN1: =IF(ISNUMBER(DataStart),DataStart+140,"") | EO1: =IF(ISNUMBER(DataStart),DataStart+141,"") | EP1: =IF(ISNUMBER(DataStart),DataStart+142,"") | EQ1: =IF(ISNUMBER(DataStart),DataStart+143,"") | ER1: =IF(ISNUMBER(DataStart),DataStart+144,"") | ES1: =IF(ISNUMBER(DataStart),DataStart+145,"") | ET1: =IF(ISNUMBER(DataStart),DataStart+146,"") | EU1: =IF(ISNUMBER(DataStart),DataStart+147,"") | EV1: =IF(ISNUMBER(DataStart),DataStart+148,"") | EW1: =IF(ISNUMBER(DataStart),DataStart+149,"") | EX1: =IF(ISNUMBER(DataStart),DataStart+150,"") | EY1: =IF(ISNUMBER(DataStart),DataStart+151,"") | EZ1: =IF(ISNUMBER(DataStart),DataStart+152,"") | FA1: =IF(ISNUMBER(DataStart),DataStart+153,"") | FB1: =IF(ISNUMBER(DataStart),DataStart+154,"") | FC1: =IF(ISNUMBER(DataStart),DataStart+155,"") | FD1: =IF(ISNUMBER(DataStart),DataStart+156,"") | FE1: =IF(ISNUMBER(DataStart),DataStart+157,"") | FF1: =IF(ISNUMBER(DataStart),DataStart+158,"") | FG1: =IF(ISNUMBER(DataStart),DataStart+159,"") | FH1: =IF(ISNUMBER(DataStart),DataStart+160,"") | FI1: =IF(ISNUMBER(DataStart),DataStart+161,"") | FJ1: =IF(ISNUMBER(DataStart),DataStart+162,"") | FK1: =IF(ISNUMBER(DataStart),DataStart+163,"") | FL1: =IF(ISNUMBER(DataStart),DataStart+164,"") | FM1: =IF(ISNUMBER(DataStart),DataStart+165,"") | FN1: =IF(ISNUMBER(DataStart),DataStart+166,"") | FO1: =IF(ISNUMBER(DataStart),DataStart+167,"") | FP1: =IF(ISNUMBER(DataStart),DataStart+168,"") | FQ1: =IF(ISNUMBER(DataStart),DataStart+169,"")
B2: Weekday | D2: =IF(D1="","",TEXT(D1,"ddd")) | E2: =IF(E1="","",TEXT(E1,"ddd")) | F2: =IF(F1="","",TEXT(F1,"ddd")) | G2: =IF(G1="","",TEXT(G1,"ddd")) | H2: =IF(H1="","",TEXT(H1,"ddd")) | I2: =IF(I1="","",TEXT(I1,"ddd")) | J2: =IF(J1="","",TEXT(J1,"ddd")) | K2: =IF(K1="","",TEXT(K1,"ddd")) | ... FQ2: =IF(FQ1="","",TEXT(FQ1,"ddd"))
B3: Days after transplanting | D3: =IF(D1="","",D1-TransDate) | E3: =IF(E1="","",E1-TransDate) | F3: =IF(F1="","",F1-TransDate) | G3: =IF(G1="","",G1-TransDate) | H3: =IF(H1="","",H1-TransDate) | I3: =IF(I1="","",I1-TransDate) | J3: =IF(J1="","",J1-TransDate) | K3: =IF(K1="","",K1-TransDate) | ... FQ3: =IF(FQ1="","",FQ1-TransDate)
B4: Days after sowing | D4: =IF(OR(D1="",NOT(ISNUMBER(SowDate))),"",D1-SowDate) | E4: =IF(OR(E1="",NOT(ISNUMBER(SowDate))),"",E1-SowDate) | F4: =IF(OR(F1="",NOT(ISNUMBER(SowDate))),"",F1-SowDate) | G4: =IF(OR(G1="",NOT(ISNUMBER(SowDate))),"",G1-SowDate) | H4: =IF(OR(H1="",NOT(ISNUMBER(SowDate))),"",H1-SowDate) | I4: =IF(OR(I1="",NOT(ISNUMBER(SowDate))),"",I1-SowDate) | J4: =IF(OR(J1="",NOT(ISNUMBER(SowDate))),"",J1-SowDate) | K4: =IF(OR(K1="",NOT(ISNUMBER(SowDate))),"",K1-SowDate) | ... FQ4: =IF(OR(FQ1="",NOT(ISNUMBER(SowDate))),"",FQ1-SowDate)
B5: Days after heading | D5: =IF(OR(D1="",NOT(ISNUMBER(HeadD))),"",D1-HeadD) | E5: =IF(OR(E1="",NOT(ISNUMBER(HeadD))),"",E1-HeadD) | F5: =IF(OR(F1="",NOT(ISNUMBER(HeadD))),"",F1-HeadD) | G5: =IF(OR(G1="",NOT(ISNUMBER(HeadD))),"",G1-HeadD) | H5: =IF(OR(H1="",NOT(ISNUMBER(HeadD))),"",H1-HeadD) | I5: =IF(OR(I1="",NOT(ISNUMBER(HeadD))),"",I1-HeadD) | J5: =IF(OR(J1="",NOT(ISNUMBER(HeadD))),"",J1-HeadD) | K5: =IF(OR(K1="",NOT(ISNUMBER(HeadD))),"",K1-HeadD) | ... FQ5: =IF(OR(FQ1="",NOT(ISNUMBER(HeadD))),"",FQ1-HeadD)
B6: Stage (schedule) | D6: =IF(D1="","",TRIM(IF(AND(ISNUMBER(PitanS),D1>=PitanS,D1<=PitanE),"Pitan ","")&IF(AND(ISNUMBER(MDS),D1>=MDS,D1<=MDE),"MD ","")&IF(AND(ISNUMBER(FloodS),D1>=FloodS,D1<FloodE),"PI-flood ","")&IF(AND(ISNUMBER(C1S),D1>=C1S,D1<=C3E),"3F4D-"&MIN(6,INT((D1-C1S)/cfg_13)+1)&" ","")&IF(AND(ISNUMBER(HeadD),D1=HeadD),"Heading",""))) | E6: =IF(E1="","",TRIM(IF(AND(ISNUMBER(PitanS),E1>=PitanS,E1<=PitanE),"Pitan ","")&IF(AND(ISNUMBER(MDS),E1>=MDS,E1<=MDE),"MD ","")&IF(AND(ISNUMBER(FloodS),E1>=FloodS,E1<FloodE),"PI-flood ","")&IF(AND(ISNUMBER(C1S),E1>=C1S,E1<=C3E),"3F4D-"&MIN(6,INT((E1-C1S)/cfg_13)+1)&" ","")&IF(AND(ISNUMBER(HeadD),E1=HeadD),"Heading",""))) | F6: =IF(F1="","",TRIM(IF(AND(ISNUMBER(PitanS),F1>=PitanS,F1<=PitanE),"Pitan ","")&IF(AND(ISNUMBER(MDS),F1>=MDS,F1<=MDE),"MD ","")&IF(AND(ISNUMBER(FloodS),F1>=FloodS,F1<FloodE),"PI-flood ","")&IF(AND(ISNUMBER(C1S),F1>=C1S,F1<=C3E),"3F4D-"&MIN(6,INT((F1-C1S)/cfg_13)+1)&" ","")&IF(AND(ISNUMBER(HeadD),F1=HeadD),"Heading",""))) | G6: =IF(G1="","",TRIM(IF(AND(ISNUMBER(PitanS),G1>=PitanS,G1<=PitanE),"Pitan ","")&IF(AND(ISNUMBER(MDS),G1>=MDS,G1<=MDE),"MD ","")&IF(AND(ISNUMBER(FloodS),G1>=FloodS,G1<FloodE),"PI-flood ","")&IF(AND(ISNUMBER(C1S),G1>=C1S,G1<=C3E),"3F4D-"&MIN(6,INT((G1-C1S)/cfg_13)+1)&" ","")&IF(AND(ISNUMBER(HeadD),G1=HeadD),"Heading",""))) | H6: =IF(H1="","",TRIM(IF(AND(ISNUMBER(PitanS),H1>=PitanS,H1<=PitanE),"Pitan ","")&IF(AND(ISNUMBER(MDS),H1>=MDS,H1<=MDE),"MD ","")&IF(AND(ISNUMBER(FloodS),H1>=FloodS,H1<FloodE),"PI-flood ","")&IF(AND(ISNUMBER(C1S),H1>=C1S,H1<=C3E),"3F4D-"&MIN(6,INT((H1-C1S)/cfg_13)+1)&" ","")&IF(AND(ISNUMBER(HeadD),H1=HeadD),"Heading",""))) | I6: =IF(I1="","",TRIM(IF(AND(ISNUMBER(PitanS),I1>=PitanS,I1<=PitanE),"Pitan ","")&IF(AND(ISNUMBER(MDS),I1>=MDS,I1<=MDE),"MD ","")&IF(AND(ISNUMBER(FloodS),I1>=FloodS,I1<FloodE),"PI-flood ","")&IF(AND(ISNUMBER(C1S),I1>=C1S,I1<=C3E),"3F4D-"&MIN(6,INT((I1-C1S)/cfg_13)+1)&" ","")&IF(AND(ISNUMBER(HeadD),I1=HeadD),"Heading",""))) | J6: =IF(J1="","",TRIM(IF(AND(ISNUMBER(PitanS),J1>=PitanS,J1<=PitanE),"Pitan ","")&IF(AND(ISNUMBER(MDS),J1>=MDS,J1<=MDE),"MD ","")&IF(AND(ISNUMBER(FloodS),J1>=FloodS,J1<FloodE),"PI-flood ","")&IF(AND(ISNUMBER(C1S),J1>=C1S,J1<=C3E),"3F4D-"&MIN(6,INT((J1-C1S)/cfg_13)+1)&" ","")&IF(AND(ISNUMBER(HeadD),J1=HeadD),"Heading",""))) | K6: =IF(K1="","",TRIM(IF(AND(ISNUMBER(PitanS),K1>=PitanS,K1<=PitanE),"Pitan ","")&IF(AND(ISNUMBER(MDS),K1>=MDS,K1<=MDE),"MD ","")&IF(AND(ISNUMBER(FloodS),K1>=FloodS,K1<FloodE),"PI-flood ","")&IF(AND(ISNUMBER(C1S),K1>=C1S,K1<=C3E),"3F4D-"&MIN(6,INT((K1-C1S)/cfg_13)+1)&" ","")&IF(AND(ISNUMBER(HeadD),K1=HeadD),"Heading",""))) | ... FQ6: =IF(FQ1="","",TRIM(IF(AND(ISNUMBER(PitanS),FQ1>=PitanS,FQ1<=PitanE),"Pitan ","")&IF(AND(ISNUMBER(MDS),FQ1>=MDS,FQ1<=MDE),"MD ","")&IF(AND(ISNUMBER(FloodS),FQ1>=FloodS,FQ1<FloodE),"PI-flood ","")&IF(AND(ISNUMBER(C1S),FQ1>=C1S,FQ1<=C3E),"3F4D-"&MIN(6,INT((FQ1-C1S)/cfg_13)+1)&" ","")&IF(AND(ISNUMBER(HeadD),FQ1=HeadD),"Heading","")))
A7: Both | B7: Weather / আবহাওয়া
A8: Both | B8: Rain fall (mm) / বৃষ্টি | C8: =SUM($D$8:$FQ$8)
A9: Both | B9: Temperature (°C) / তাপমাত্রা
A10: Both | B10: Humidity (%) / আর্দ্রতা
A11: FP | B11: Farmers practice plot
A12: FP | B12: Daily m (cm) * / দৈনিক m | C12: =COUNT($D$12:$FQ$12)&" days"
A13: FP | B13: Daily water level (cm) / পানির স্তর | D13: =IF(OR(D1="",NOT(ISNUMBER(D12)),D14=""),"",ROUND(D12-D14+D15,1)) | E13: =IF(OR(E1="",NOT(ISNUMBER(E12)),E14=""),"",ROUND(E12-E14+E15,1)) | F13: =IF(OR(F1="",NOT(ISNUMBER(F12)),F14=""),"",ROUND(F12-F14+F15,1)) | G13: =IF(OR(G1="",NOT(ISNUMBER(G12)),G14=""),"",ROUND(G12-G14+G15,1)) | H13: =IF(OR(H1="",NOT(ISNUMBER(H12)),H14=""),"",ROUND(H12-H14+H15,1)) | I13: =IF(OR(I1="",NOT(ISNUMBER(I12)),I14=""),"",ROUND(I12-I14+I15,1)) | J13: =IF(OR(J1="",NOT(ISNUMBER(J12)),J14=""),"",ROUND(J12-J14+J15,1)) | K13: =IF(OR(K1="",NOT(ISNUMBER(K12)),K14=""),"",ROUND(K12-K14+K15,1)) | ... FQ13: =IF(OR(FQ1="",NOT(ISNUMBER(FQ12)),FQ14=""),"",ROUND(FQ12-FQ14+FQ15,1))
A14: FP | B14: TP (cm) | D14: =IF(D31="","",AVERAGEIFS('TP-b'!$C$3:$C$60,'TP-b'!$A$3:$A$60,"FP",'TP-b'!$B$3:$B$60,D31,'TP-b'!$E$3:$E$60,1)) | E14: =IF(E31="","",AVERAGEIFS('TP-b'!$C$3:$C$60,'TP-b'!$A$3:$A$60,"FP",'TP-b'!$B$3:$B$60,E31,'TP-b'!$E$3:$E$60,1)) | F14: =IF(F31="","",AVERAGEIFS('TP-b'!$C$3:$C$60,'TP-b'!$A$3:$A$60,"FP",'TP-b'!$B$3:$B$60,F31,'TP-b'!$E$3:$E$60,1)) | G14: =IF(G31="","",AVERAGEIFS('TP-b'!$C$3:$C$60,'TP-b'!$A$3:$A$60,"FP",'TP-b'!$B$3:$B$60,G31,'TP-b'!$E$3:$E$60,1)) | H14: =IF(H31="","",AVERAGEIFS('TP-b'!$C$3:$C$60,'TP-b'!$A$3:$A$60,"FP",'TP-b'!$B$3:$B$60,H31,'TP-b'!$E$3:$E$60,1)) | I14: =IF(I31="","",AVERAGEIFS('TP-b'!$C$3:$C$60,'TP-b'!$A$3:$A$60,"FP",'TP-b'!$B$3:$B$60,I31,'TP-b'!$E$3:$E$60,1)) | J14: =IF(J31="","",AVERAGEIFS('TP-b'!$C$3:$C$60,'TP-b'!$A$3:$A$60,"FP",'TP-b'!$B$3:$B$60,J31,'TP-b'!$E$3:$E$60,1)) | K14: =IF(K31="","",AVERAGEIFS('TP-b'!$C$3:$C$60,'TP-b'!$A$3:$A$60,"FP",'TP-b'!$B$3:$B$60,K31,'TP-b'!$E$3:$E$60,1)) | ... FQ14: =IF(FQ31="","",AVERAGEIFS('TP-b'!$C$3:$C$60,'TP-b'!$A$3:$A$60,"FP",'TP-b'!$B$3:$B$60,FQ31,'TP-b'!$E$3:$E$60,1))
A15: FP | B15: b (cm) | D15: =IF(D31="","",AVERAGEIFS('TP-b'!$D$3:$D$60,'TP-b'!$A$3:$A$60,"FP",'TP-b'!$B$3:$B$60,D31,'TP-b'!$E$3:$E$60,1)) | E15: =IF(E31="","",AVERAGEIFS('TP-b'!$D$3:$D$60,'TP-b'!$A$3:$A$60,"FP",'TP-b'!$B$3:$B$60,E31,'TP-b'!$E$3:$E$60,1)) | F15: =IF(F31="","",AVERAGEIFS('TP-b'!$D$3:$D$60,'TP-b'!$A$3:$A$60,"FP",'TP-b'!$B$3:$B$60,F31,'TP-b'!$E$3:$E$60,1)) | G15: =IF(G31="","",AVERAGEIFS('TP-b'!$D$3:$D$60,'TP-b'!$A$3:$A$60,"FP",'TP-b'!$B$3:$B$60,G31,'TP-b'!$E$3:$E$60,1)) | H15: =IF(H31="","",AVERAGEIFS('TP-b'!$D$3:$D$60,'TP-b'!$A$3:$A$60,"FP",'TP-b'!$B$3:$B$60,H31,'TP-b'!$E$3:$E$60,1)) | I15: =IF(I31="","",AVERAGEIFS('TP-b'!$D$3:$D$60,'TP-b'!$A$3:$A$60,"FP",'TP-b'!$B$3:$B$60,I31,'TP-b'!$E$3:$E$60,1)) | J15: =IF(J31="","",AVERAGEIFS('TP-b'!$D$3:$D$60,'TP-b'!$A$3:$A$60,"FP",'TP-b'!$B$3:$B$60,J31,'TP-b'!$E$3:$E$60,1)) | K15: =IF(K31="","",AVERAGEIFS('TP-b'!$D$3:$D$60,'TP-b'!$A$3:$A$60,"FP",'TP-b'!$B$3:$B$60,K31,'TP-b'!$E$3:$E$60,1)) | ... FQ15: =IF(FQ31="","",AVERAGEIFS('TP-b'!$D$3:$D$60,'TP-b'!$A$3:$A$60,"FP",'TP-b'!$B$3:$B$60,FQ31,'TP-b'!$E$3:$E$60,1))
A16: FP | B16: Before irrigation m (cm) / সেচের আগে m | C16: =COUNT($D$21:$FQ$21)&" irrig."
A17: FP | B17: After irrigation m (cm) / সেচের পরে m
A18: FP | B18: Irrigation time (min:sec) / সেচের সময়
A19: FP | B19: Before irrigation water level (cm) / সেচের আগে স্তর | D19: =IF(AND(ISNUMBER(D16),ISNUMBER(D17),D14<>""),ROUND(D16-D14+D15,1),"") | E19: =IF(AND(ISNUMBER(E16),ISNUMBER(E17),E14<>""),ROUND(E16-E14+E15,1),"") | F19: =IF(AND(ISNUMBER(F16),ISNUMBER(F17),F14<>""),ROUND(F16-F14+F15,1),"") | G19: =IF(AND(ISNUMBER(G16),ISNUMBER(G17),G14<>""),ROUND(G16-G14+G15,1),"") | H19: =IF(AND(ISNUMBER(H16),ISNUMBER(H17),H14<>""),ROUND(H16-H14+H15,1),"") | I19: =IF(AND(ISNUMBER(I16),ISNUMBER(I17),I14<>""),ROUND(I16-I14+I15,1),"") | J19: =IF(AND(ISNUMBER(J16),ISNUMBER(J17),J14<>""),ROUND(J16-J14+J15,1),"") | K19: =IF(AND(ISNUMBER(K16),ISNUMBER(K17),K14<>""),ROUND(K16-K14+K15,1),"") | ... FQ19: =IF(AND(ISNUMBER(FQ16),ISNUMBER(FQ17),FQ14<>""),ROUND(FQ16-FQ14+FQ15,1),"")
A20: FP | B20: After irrigation water level (cm) / সেচের পরে স্তর | D20: =IF(AND(ISNUMBER(D16),ISNUMBER(D17),D14<>""),ROUND(D17-D14+D15,1),"") | E20: =IF(AND(ISNUMBER(E16),ISNUMBER(E17),E14<>""),ROUND(E17-E14+E15,1),"") | F20: =IF(AND(ISNUMBER(F16),ISNUMBER(F17),F14<>""),ROUND(F17-F14+F15,1),"") | G20: =IF(AND(ISNUMBER(G16),ISNUMBER(G17),G14<>""),ROUND(G17-G14+G15,1),"") | H20: =IF(AND(ISNUMBER(H16),ISNUMBER(H17),H14<>""),ROUND(H17-H14+H15,1),"") | I20: =IF(AND(ISNUMBER(I16),ISNUMBER(I17),I14<>""),ROUND(I17-I14+I15,1),"") | J20: =IF(AND(ISNUMBER(J16),ISNUMBER(J17),J14<>""),ROUND(J17-J14+J15,1),"") | K20: =IF(AND(ISNUMBER(K16),ISNUMBER(K17),K14<>""),ROUND(K17-K14+K15,1),"") | ... FQ20: =IF(AND(ISNUMBER(FQ16),ISNUMBER(FQ17),FQ14<>""),ROUND(FQ17-FQ14+FQ15,1),"")
A21: FP | B21: Irrigation (mm) / সেচ (মিমি) | C21: =ROUND(SUM($D$21:$FQ$21),0) | D21: =IF(AND(ISNUMBER(D12),ISNUMBER(D19),ISNUMBER(D20)),ROUND((D20-MAX(D19,0))*10,1),"") | E21: =IF(AND(ISNUMBER(E12),ISNUMBER(E19),ISNUMBER(E20)),ROUND((E20-MAX(E19,0))*10,1),"") | F21: =IF(AND(ISNUMBER(F12),ISNUMBER(F19),ISNUMBER(F20)),ROUND((F20-MAX(F19,0))*10,1),"") | G21: =IF(AND(ISNUMBER(G12),ISNUMBER(G19),ISNUMBER(G20)),ROUND((G20-MAX(G19,0))*10,1),"") | H21: =IF(AND(ISNUMBER(H12),ISNUMBER(H19),ISNUMBER(H20)),ROUND((H20-MAX(H19,0))*10,1),"") | I21: =IF(AND(ISNUMBER(I12),ISNUMBER(I19),ISNUMBER(I20)),ROUND((I20-MAX(I19,0))*10,1),"") | J21: =IF(AND(ISNUMBER(J12),ISNUMBER(J19),ISNUMBER(J20)),ROUND((J20-MAX(J19,0))*10,1),"") | K21: =IF(AND(ISNUMBER(K12),ISNUMBER(K19),ISNUMBER(K20)),ROUND((K20-MAX(K19,0))*10,1),"") | ... FQ21: =IF(AND(ISNUMBER(FQ12),ISNUMBER(FQ19),ISNUMBER(FQ20)),ROUND((FQ20-MAX(FQ19,0))*10,1),"")
A22: FP | B22: Cumulative irrigation (mm) / মোট সেচ | C22: =IF(COUNT($D$22:$FQ$22)=0,"",MAX($D$22:$FQ$22)) | D22: =IF(D13="","",ROUND(SUM($D$21:D21),1)) | E22: =IF(E13="","",ROUND(SUM($D$21:E21),1)) | F22: =IF(F13="","",ROUND(SUM($D$21:F21),1)) | G22: =IF(G13="","",ROUND(SUM($D$21:G21),1)) | H22: =IF(H13="","",ROUND(SUM($D$21:H21),1)) | I22: =IF(I13="","",ROUND(SUM($D$21:I21),1)) | J22: =IF(J13="","",ROUND(SUM($D$21:J21),1)) | K22: =IF(K13="","",ROUND(SUM($D$21:K21),1)) | ... FQ22: =IF(FQ13="","",ROUND(SUM($D$21:FQ21),1))
A23: FP | B23: Daily water-level decrease (mm) / দৈনিক হ্রাস | D23: ="" | E23: =IF(AND(ISNUMBER(D32),ISNUMBER(E13)),ROUND((D32-E13)*10,1),"") | F23: =IF(AND(ISNUMBER(E32),ISNUMBER(F13)),ROUND((E32-F13)*10,1),"") | G23: =IF(AND(ISNUMBER(F32),ISNUMBER(G13)),ROUND((F32-G13)*10,1),"") | H23: =IF(AND(ISNUMBER(G32),ISNUMBER(H13)),ROUND((G32-H13)*10,1),"") | I23: =IF(AND(ISNUMBER(H32),ISNUMBER(I13)),ROUND((H32-I13)*10,1),"") | J23: =IF(AND(ISNUMBER(I32),ISNUMBER(J13)),ROUND((I32-J13)*10,1),"") | K23: =IF(AND(ISNUMBER(J32),ISNUMBER(K13)),ROUND((J32-K13)*10,1),"") | L23: =IF(AND(ISNUMBER(K32),ISNUMBER(L13)),ROUND((K32-L13)*10,1),"") | ... FQ23: =IF(AND(ISNUMBER(FP32),ISNUMBER(FQ13)),ROUND((FP32-FQ13)*10,1),"")
A24: FP | B24: Field condition / মাঠের অবস্থা
A25: FP | B25: Condition / অবস্থা
A26: FP | B26: Farmer (land owner) min / কৃষকের সময় (মিনিট) | C26: =SUM($D$26:$FQ$26)
A27: FP | B27: Farmer work contents / কৃষকের কাজ
A28: FP | B28: Labour BDT / শ্রমিক (টাকা) | C28: =SUM($D$28:$FQ$28)
A29: FP | B29: Labour work contents / শ্রমিকের কাজ
A30: FP | B30: Check / পরীক্ষা | D30: =IF(D1="","",IF(AND(ISNUMBER(D13),OR(D13<-30,D13>20)),"WL out of range; ","")&IF(AND(ISNUMBER(D12),D13=""),"no TP/b; ","")&IF(AND(ISNUMBER(D19),ISNUMBER(D20)),IF(D20<D19,"After<Before; ",""),"")&IF(AND(ISNUMBER(D12),ISNUMBER(D16)<>ISNUMBER(D17)),"irrigation readings missing; ","")&IF(ISNUMBER(D23),IF(AND(ABS(D23)>50,NOT(N(D8)>0)),"WL jump >5 cm; ",""),"")) | E30: =IF(E1="","",IF(AND(ISNUMBER(E13),OR(E13<-30,E13>20)),"WL out of range; ","")&IF(AND(ISNUMBER(E12),E13=""),"no TP/b; ","")&IF(AND(ISNUMBER(E19),ISNUMBER(E20)),IF(E20<E19,"After<Before; ",""),"")&IF(AND(ISNUMBER(E12),ISNUMBER(E16)<>ISNUMBER(E17)),"irrigation readings missing; ","")&IF(ISNUMBER(E23),IF(AND(ABS(E23)>50,NOT(N(E8)>0)),"WL jump >5 cm; ",""),"")) | F30: =IF(F1="","",IF(AND(ISNUMBER(F13),OR(F13<-30,F13>20)),"WL out of range; ","")&IF(AND(ISNUMBER(F12),F13=""),"no TP/b; ","")&IF(AND(ISNUMBER(F19),ISNUMBER(F20)),IF(F20<F19,"After<Before; ",""),"")&IF(AND(ISNUMBER(F12),ISNUMBER(F16)<>ISNUMBER(F17)),"irrigation readings missing; ","")&IF(ISNUMBER(F23),IF(AND(ABS(F23)>50,NOT(N(F8)>0)),"WL jump >5 cm; ",""),"")) | G30: =IF(G1="","",IF(AND(ISNUMBER(G13),OR(G13<-30,G13>20)),"WL out of range; ","")&IF(AND(ISNUMBER(G12),G13=""),"no TP/b; ","")&IF(AND(ISNUMBER(G19),ISNUMBER(G20)),IF(G20<G19,"After<Before; ",""),"")&IF(AND(ISNUMBER(G12),ISNUMBER(G16)<>ISNUMBER(G17)),"irrigation readings missing; ","")&IF(ISNUMBER(G23),IF(AND(ABS(G23)>50,NOT(N(G8)>0)),"WL jump >5 cm; ",""),"")) | H30: =IF(H1="","",IF(AND(ISNUMBER(H13),OR(H13<-30,H13>20)),"WL out of range; ","")&IF(AND(ISNUMBER(H12),H13=""),"no TP/b; ","")&IF(AND(ISNUMBER(H19),ISNUMBER(H20)),IF(H20<H19,"After<Before; ",""),"")&IF(AND(ISNUMBER(H12),ISNUMBER(H16)<>ISNUMBER(H17)),"irrigation readings missing; ","")&IF(ISNUMBER(H23),IF(AND(ABS(H23)>50,NOT(N(H8)>0)),"WL jump >5 cm; ",""),"")) | I30: =IF(I1="","",IF(AND(ISNUMBER(I13),OR(I13<-30,I13>20)),"WL out of range; ","")&IF(AND(ISNUMBER(I12),I13=""),"no TP/b; ","")&IF(AND(ISNUMBER(I19),ISNUMBER(I20)),IF(I20<I19,"After<Before; ",""),"")&IF(AND(ISNUMBER(I12),ISNUMBER(I16)<>ISNUMBER(I17)),"irrigation readings missing; ","")&IF(ISNUMBER(I23),IF(AND(ABS(I23)>50,NOT(N(I8)>0)),"WL jump >5 cm; ",""),"")) | J30: =IF(J1="","",IF(AND(ISNUMBER(J13),OR(J13<-30,J13>20)),"WL out of range; ","")&IF(AND(ISNUMBER(J12),J13=""),"no TP/b; ","")&IF(AND(ISNUMBER(J19),ISNUMBER(J20)),IF(J20<J19,"After<Before; ",""),"")&IF(AND(ISNUMBER(J12),ISNUMBER(J16)<>ISNUMBER(J17)),"irrigation readings missing; ","")&IF(ISNUMBER(J23),IF(AND(ABS(J23)>50,NOT(N(J8)>0)),"WL jump >5 cm; ",""),"")) | K30: =IF(K1="","",IF(AND(ISNUMBER(K13),OR(K13<-30,K13>20)),"WL out of range; ","")&IF(AND(ISNUMBER(K12),K13=""),"no TP/b; ","")&IF(AND(ISNUMBER(K19),ISNUMBER(K20)),IF(K20<K19,"After<Before; ",""),"")&IF(AND(ISNUMBER(K12),ISNUMBER(K16)<>ISNUMBER(K17)),"irrigation readings missing; ","")&IF(ISNUMBER(K23),IF(AND(ABS(K23)>50,NOT(N(K8)>0)),"WL jump >5 cm; ",""),"")) | ... FQ30: =IF(FQ1="","",IF(AND(ISNUMBER(FQ13),OR(FQ13<-30,FQ13>20)),"WL out of range; ","")&IF(AND(ISNUMBER(FQ12),FQ13=""),"no TP/b; ","")&IF(AND(ISNUMBER(FQ19),ISNUMBER(FQ20)),IF(FQ20<FQ19,"After<Before; ",""),"")&IF(AND(ISNUMBER(FQ12),ISNUMBER(FQ16)<>ISNUMBER(FQ17)),"irrigation readings missing; ","")&IF(ISNUMBER(FQ23),IF(AND(ABS(FQ23)>50,NOT(N(FQ8)>0)),"WL jump >5 cm; ",""),""))
A31: FP | B31: (TP-b date) | D31: =IF(D1="","",IF(_xlfn.MAXIFS('TP-b'!$B$3:$B$60,'TP-b'!$A$3:$A$60,"FP",'TP-b'!$E$3:$E$60,1,'TP-b'!$B$3:$B$60,"<="&D1)>0,_xlfn.MAXIFS('TP-b'!$B$3:$B$60,'TP-b'!$A$3:$A$60,"FP",'TP-b'!$E$3:$E$60,1,'TP-b'!$B$3:$B$60,"<="&D1),IF(_xlfn.MINIFS('TP-b'!$B$3:$B$60,'TP-b'!$A$3:$A$60,"FP",'TP-b'!$E$3:$E$60,1)>0,_xlfn.MINIFS('TP-b'!$B$3:$B$60,'TP-b'!$A$3:$A$60,"FP",'TP-b'!$E$3:$E$60,1),""))) | E31: =IF(E1="","",IF(_xlfn.MAXIFS('TP-b'!$B$3:$B$60,'TP-b'!$A$3:$A$60,"FP",'TP-b'!$E$3:$E$60,1,'TP-b'!$B$3:$B$60,"<="&E1)>0,_xlfn.MAXIFS('TP-b'!$B$3:$B$60,'TP-b'!$A$3:$A$60,"FP",'TP-b'!$E$3:$E$60,1,'TP-b'!$B$3:$B$60,"<="&E1),IF(_xlfn.MINIFS('TP-b'!$B$3:$B$60,'TP-b'!$A$3:$A$60,"FP",'TP-b'!$E$3:$E$60,1)>0,_xlfn.MINIFS('TP-b'!$B$3:$B$60,'TP-b'!$A$3:$A$60,"FP",'TP-b'!$E$3:$E$60,1),""))) | F31: =IF(F1="","",IF(_xlfn.MAXIFS('TP-b'!$B$3:$B$60,'TP-b'!$A$3:$A$60,"FP",'TP-b'!$E$3:$E$60,1,'TP-b'!$B$3:$B$60,"<="&F1)>0,_xlfn.MAXIFS('TP-b'!$B$3:$B$60,'TP-b'!$A$3:$A$60,"FP",'TP-b'!$E$3:$E$60,1,'TP-b'!$B$3:$B$60,"<="&F1),IF(_xlfn.MINIFS('TP-b'!$B$3:$B$60,'TP-b'!$A$3:$A$60,"FP",'TP-b'!$E$3:$E$60,1)>0,_xlfn.MINIFS('TP-b'!$B$3:$B$60,'TP-b'!$A$3:$A$60,"FP",'TP-b'!$E$3:$E$60,1),""))) | G31: =IF(G1="","",IF(_xlfn.MAXIFS('TP-b'!$B$3:$B$60,'TP-b'!$A$3:$A$60,"FP",'TP-b'!$E$3:$E$60,1,'TP-b'!$B$3:$B$60,"<="&G1)>0,_xlfn.MAXIFS('TP-b'!$B$3:$B$60,'TP-b'!$A$3:$A$60,"FP",'TP-b'!$E$3:$E$60,1,'TP-b'!$B$3:$B$60,"<="&G1),IF(_xlfn.MINIFS('TP-b'!$B$3:$B$60,'TP-b'!$A$3:$A$60,"FP",'TP-b'!$E$3:$E$60,1)>0,_xlfn.MINIFS('TP-b'!$B$3:$B$60,'TP-b'!$A$3:$A$60,"FP",'TP-b'!$E$3:$E$60,1),""))) | H31: =IF(H1="","",IF(_xlfn.MAXIFS('TP-b'!$B$3:$B$60,'TP-b'!$A$3:$A$60,"FP",'TP-b'!$E$3:$E$60,1,'TP-b'!$B$3:$B$60,"<="&H1)>0,_xlfn.MAXIFS('TP-b'!$B$3:$B$60,'TP-b'!$A$3:$A$60,"FP",'TP-b'!$E$3:$E$60,1,'TP-b'!$B$3:$B$60,"<="&H1),IF(_xlfn.MINIFS('TP-b'!$B$3:$B$60,'TP-b'!$A$3:$A$60,"FP",'TP-b'!$E$3:$E$60,1)>0,_xlfn.MINIFS('TP-b'!$B$3:$B$60,'TP-b'!$A$3:$A$60,"FP",'TP-b'!$E$3:$E$60,1),""))) | I31: =IF(I1="","",IF(_xlfn.MAXIFS('TP-b'!$B$3:$B$60,'TP-b'!$A$3:$A$60,"FP",'TP-b'!$E$3:$E$60,1,'TP-b'!$B$3:$B$60,"<="&I1)>0,_xlfn.MAXIFS('TP-b'!$B$3:$B$60,'TP-b'!$A$3:$A$60,"FP",'TP-b'!$E$3:$E$60,1,'TP-b'!$B$3:$B$60,"<="&I1),IF(_xlfn.MINIFS('TP-b'!$B$3:$B$60,'TP-b'!$A$3:$A$60,"FP",'TP-b'!$E$3:$E$60,1)>0,_xlfn.MINIFS('TP-b'!$B$3:$B$60,'TP-b'!$A$3:$A$60,"FP",'TP-b'!$E$3:$E$60,1),""))) | J31: =IF(J1="","",IF(_xlfn.MAXIFS('TP-b'!$B$3:$B$60,'TP-b'!$A$3:$A$60,"FP",'TP-b'!$E$3:$E$60,1,'TP-b'!$B$3:$B$60,"<="&J1)>0,_xlfn.MAXIFS('TP-b'!$B$3:$B$60,'TP-b'!$A$3:$A$60,"FP",'TP-b'!$E$3:$E$60,1,'TP-b'!$B$3:$B$60,"<="&J1),IF(_xlfn.MINIFS('TP-b'!$B$3:$B$60,'TP-b'!$A$3:$A$60,"FP",'TP-b'!$E$3:$E$60,1)>0,_xlfn.MINIFS('TP-b'!$B$3:$B$60,'TP-b'!$A$3:$A$60,"FP",'TP-b'!$E$3:$E$60,1),""))) | K31: =IF(K1="","",IF(_xlfn.MAXIFS('TP-b'!$B$3:$B$60,'TP-b'!$A$3:$A$60,"FP",'TP-b'!$E$3:$E$60,1,'TP-b'!$B$3:$B$60,"<="&K1)>0,_xlfn.MAXIFS('TP-b'!$B$3:$B$60,'TP-b'!$A$3:$A$60,"FP",'TP-b'!$E$3:$E$60,1,'TP-b'!$B$3:$B$60,"<="&K1),IF(_xlfn.MINIFS('TP-b'!$B$3:$B$60,'TP-b'!$A$3:$A$60,"FP",'TP-b'!$E$3:$E$60,1)>0,_xlfn.MINIFS('TP-b'!$B$3:$B$60,'TP-b'!$A$3:$A$60,"FP",'TP-b'!$E$3:$E$60,1),""))) | ... FQ31: =IF(FQ1="","",IF(_xlfn.MAXIFS('TP-b'!$B$3:$B$60,'TP-b'!$A$3:$A$60,"FP",'TP-b'!$E$3:$E$60,1,'TP-b'!$B$3:$B$60,"<="&FQ1)>0,_xlfn.MAXIFS('TP-b'!$B$3:$B$60,'TP-b'!$A$3:$A$60,"FP",'TP-b'!$E$3:$E$60,1,'TP-b'!$B$3:$B$60,"<="&FQ1),IF(_xlfn.MINIFS('TP-b'!$B$3:$B$60,'TP-b'!$A$3:$A$60,"FP",'TP-b'!$E$3:$E$60,1)>0,_xlfn.MINIFS('TP-b'!$B$3:$B$60,'TP-b'!$A$3:$A$60,"FP",'TP-b'!$E$3:$E$60,1),"")))
A32: FP | B32: (end of day level) | D32: =IF(D13="","",IF(ISNUMBER(D20),D20,D13)) | E32: =IF(E13="","",IF(ISNUMBER(E20),E20,E13)) | F32: =IF(F13="","",IF(ISNUMBER(F20),F20,F13)) | G32: =IF(G13="","",IF(ISNUMBER(G20),G20,G13)) | H32: =IF(H13="","",IF(ISNUMBER(H20),H20,H13)) | I32: =IF(I13="","",IF(ISNUMBER(I20),I20,I13)) | J32: =IF(J13="","",IF(ISNUMBER(J20),J20,J13)) | K32: =IF(K13="","",IF(ISNUMBER(K20),K20,K13)) | ... FQ32: =IF(FQ13="","",IF(ISNUMBER(FQ20),FQ20,FQ13))
A33: FP | B33: (has level) | D33: =IF(ISNUMBER(D13),1,0) | E33: =IF(ISNUMBER(E13),1,0) | F33: =IF(ISNUMBER(F13),1,0) | G33: =IF(ISNUMBER(G13),1,0) | H33: =IF(ISNUMBER(H13),1,0) | I33: =IF(ISNUMBER(I13),1,0) | J33: =IF(ISNUMBER(J13),1,0) | K33: =IF(ISNUMBER(K13),1,0) | ... FQ33: =IF(ISNUMBER(FQ13),1,0)
A36: 3F4D+MD | B36: 3F4D+MD plot
A37: 3F4D+MD | B37: Daily m (cm) * / দৈনিক m | C37: =COUNT($D$37:$FQ$37)&" days"
A38: 3F4D+MD | B38: Daily water level (cm) / পানির স্তর | D38: =IF(OR(D1="",NOT(ISNUMBER(D37)),D39=""),"",ROUND(D37-D39+D40,1)) | E38: =IF(OR(E1="",NOT(ISNUMBER(E37)),E39=""),"",ROUND(E37-E39+E40,1)) | F38: =IF(OR(F1="",NOT(ISNUMBER(F37)),F39=""),"",ROUND(F37-F39+F40,1)) | G38: =IF(OR(G1="",NOT(ISNUMBER(G37)),G39=""),"",ROUND(G37-G39+G40,1)) | H38: =IF(OR(H1="",NOT(ISNUMBER(H37)),H39=""),"",ROUND(H37-H39+H40,1)) | I38: =IF(OR(I1="",NOT(ISNUMBER(I37)),I39=""),"",ROUND(I37-I39+I40,1)) | J38: =IF(OR(J1="",NOT(ISNUMBER(J37)),J39=""),"",ROUND(J37-J39+J40,1)) | K38: =IF(OR(K1="",NOT(ISNUMBER(K37)),K39=""),"",ROUND(K37-K39+K40,1)) | ... FQ38: =IF(OR(FQ1="",NOT(ISNUMBER(FQ37)),FQ39=""),"",ROUND(FQ37-FQ39+FQ40,1))
A39: 3F4D+MD | B39: TP (cm) | D39: =IF(D56="","",AVERAGEIFS('TP-b'!$C$3:$C$60,'TP-b'!$A$3:$A$60,"3F4D+MD",'TP-b'!$B$3:$B$60,D56,'TP-b'!$E$3:$E$60,1)) | E39: =IF(E56="","",AVERAGEIFS('TP-b'!$C$3:$C$60,'TP-b'!$A$3:$A$60,"3F4D+MD",'TP-b'!$B$3:$B$60,E56,'TP-b'!$E$3:$E$60,1)) | F39: =IF(F56="","",AVERAGEIFS('TP-b'!$C$3:$C$60,'TP-b'!$A$3:$A$60,"3F4D+MD",'TP-b'!$B$3:$B$60,F56,'TP-b'!$E$3:$E$60,1)) | G39: =IF(G56="","",AVERAGEIFS('TP-b'!$C$3:$C$60,'TP-b'!$A$3:$A$60,"3F4D+MD",'TP-b'!$B$3:$B$60,G56,'TP-b'!$E$3:$E$60,1)) | H39: =IF(H56="","",AVERAGEIFS('TP-b'!$C$3:$C$60,'TP-b'!$A$3:$A$60,"3F4D+MD",'TP-b'!$B$3:$B$60,H56,'TP-b'!$E$3:$E$60,1)) | I39: =IF(I56="","",AVERAGEIFS('TP-b'!$C$3:$C$60,'TP-b'!$A$3:$A$60,"3F4D+MD",'TP-b'!$B$3:$B$60,I56,'TP-b'!$E$3:$E$60,1)) | J39: =IF(J56="","",AVERAGEIFS('TP-b'!$C$3:$C$60,'TP-b'!$A$3:$A$60,"3F4D+MD",'TP-b'!$B$3:$B$60,J56,'TP-b'!$E$3:$E$60,1)) | K39: =IF(K56="","",AVERAGEIFS('TP-b'!$C$3:$C$60,'TP-b'!$A$3:$A$60,"3F4D+MD",'TP-b'!$B$3:$B$60,K56,'TP-b'!$E$3:$E$60,1)) | ... FQ39: =IF(FQ56="","",AVERAGEIFS('TP-b'!$C$3:$C$60,'TP-b'!$A$3:$A$60,"3F4D+MD",'TP-b'!$B$3:$B$60,FQ56,'TP-b'!$E$3:$E$60,1))
A40: 3F4D+MD | B40: b (cm) | D40: =IF(D56="","",AVERAGEIFS('TP-b'!$D$3:$D$60,'TP-b'!$A$3:$A$60,"3F4D+MD",'TP-b'!$B$3:$B$60,D56,'TP-b'!$E$3:$E$60,1)) | E40: =IF(E56="","",AVERAGEIFS('TP-b'!$D$3:$D$60,'TP-b'!$A$3:$A$60,"3F4D+MD",'TP-b'!$B$3:$B$60,E56,'TP-b'!$E$3:$E$60,1)) | F40: =IF(F56="","",AVERAGEIFS('TP-b'!$D$3:$D$60,'TP-b'!$A$3:$A$60,"3F4D+MD",'TP-b'!$B$3:$B$60,F56,'TP-b'!$E$3:$E$60,1)) | G40: =IF(G56="","",AVERAGEIFS('TP-b'!$D$3:$D$60,'TP-b'!$A$3:$A$60,"3F4D+MD",'TP-b'!$B$3:$B$60,G56,'TP-b'!$E$3:$E$60,1)) | H40: =IF(H56="","",AVERAGEIFS('TP-b'!$D$3:$D$60,'TP-b'!$A$3:$A$60,"3F4D+MD",'TP-b'!$B$3:$B$60,H56,'TP-b'!$E$3:$E$60,1)) | I40: =IF(I56="","",AVERAGEIFS('TP-b'!$D$3:$D$60,'TP-b'!$A$3:$A$60,"3F4D+MD",'TP-b'!$B$3:$B$60,I56,'TP-b'!$E$3:$E$60,1)) | J40: =IF(J56="","",AVERAGEIFS('TP-b'!$D$3:$D$60,'TP-b'!$A$3:$A$60,"3F4D+MD",'TP-b'!$B$3:$B$60,J56,'TP-b'!$E$3:$E$60,1)) | K40: =IF(K56="","",AVERAGEIFS('TP-b'!$D$3:$D$60,'TP-b'!$A$3:$A$60,"3F4D+MD",'TP-b'!$B$3:$B$60,K56,'TP-b'!$E$3:$E$60,1)) | ... FQ40: =IF(FQ56="","",AVERAGEIFS('TP-b'!$D$3:$D$60,'TP-b'!$A$3:$A$60,"3F4D+MD",'TP-b'!$B$3:$B$60,FQ56,'TP-b'!$E$3:$E$60,1))
A41: 3F4D+MD | B41: Before irrigation m (cm) / সেচের আগে m | C41: =COUNT($D$46:$FQ$46)&" irrig."
A42: 3F4D+MD | B42: After irrigation m (cm) / সেচের পরে m
...

Sheet Schedule_Farmer
A1: Schedule / সময়সূচি (planned dates are calculated; enter the actual dates)
M2: =IF(ISNUMBER(SowDate),SowDate-3+0,"") | N2: =IF(ISNUMBER(SowDate),SowDate-3+1,"") | O2: =IF(ISNUMBER(SowDate),SowDate-3+2,"") | P2: =IF(ISNUMBER(SowDate),SowDate-3+3,"") | Q2: =IF(ISNUMBER(SowDate),SowDate-3+4,"") | R2: =IF(ISNUMBER(SowDate),SowDate-3+5,"") | S2: =IF(ISNUMBER(SowDate),SowDate-3+6,"") | T2: =IF(ISNUMBER(SowDate),SowDate-3+7,"") | U2: =IF(ISNUMBER(SowDate),SowDate-3+8,"") | V2: =IF(ISNUMBER(SowDate),SowDate-3+9,"") | W2: =IF(ISNUMBER(SowDate),SowDate-3+10,"") | X2: =IF(ISNUMBER(SowDate),SowDate-3+11,"") | Y2: =IF(ISNUMBER(SowDate),SowDate-3+12,"") | Z2: =IF(ISNUMBER(SowDate),SowDate-3+13,"") | AA2: =IF(ISNUMBER(SowDate),SowDate-3+14,"") | AB2: =IF(ISNUMBER(SowDate),SowDate-3+15,"") | AC2: =IF(ISNUMBER(SowDate),SowDate-3+16,"") | AD2: =IF(ISNUMBER(SowDate),SowDate-3+17,"") | AE2: =IF(ISNUMBER(SowDate),SowDate-3+18,"") | AF2: =IF(ISNUMBER(SowDate),SowDate-3+19,"") | AG2: =IF(ISNUMBER(SowDate),SowDate-3+20,"") | AH2: =IF(ISNUMBER(SowDate),SowDate-3+21,"") | AI2: =IF(ISNUMBER(SowDate),SowDate-3+22,"") | AJ2: =IF(ISNUMBER(SowDate),SowDate-3+23,"") | AK2: =IF(ISNUMBER(SowDate),SowDate-3+24,"") | AL2: =IF(ISNUMBER(SowDate),SowDate-3+25,"") | AM2: =IF(ISNUMBER(SowDate),SowDate-3+26,"") | AN2: =IF(ISNUMBER(SowDate),SowDate-3+27,"") | AO2: =IF(ISNUMBER(SowDate),SowDate-3+28,"") | AP2: =IF(ISNUMBER(SowDate),SowDate-3+29,"") | AQ2: =IF(ISNUMBER(SowDate),SowDate-3+30,"") | AR2: =IF(ISNUMBER(SowDate),SowDate-3+31,"") | AS2: =IF(ISNUMBER(SowDate),SowDate-3+32,"") | AT2: =IF(ISNUMBER(SowDate),SowDate-3+33,"") | AU2: =IF(ISNUMBER(SowDate),SowDate-3+34,"") | AV2: =IF(ISNUMBER(SowDate),SowDate-3+35,"") | AW2: =IF(ISNUMBER(SowDate),SowDate-3+36,"") | AX2: =IF(ISNUMBER(SowDate),SowDate-3+37,"") | AY2: =IF(ISNUMBER(SowDate),SowDate-3+38,"") | AZ2: =IF(ISNUMBER(SowDate),SowDate-3+39,"") | BA2: =IF(ISNUMBER(SowDate),SowDate-3+40,"") | BB2: =IF(ISNUMBER(SowDate),SowDate-3+41,"") | BC2: =IF(ISNUMBER(SowDate),SowDate-3+42,"") | BD2: =IF(ISNUMBER(SowDate),SowDate-3+43,"") | BE2: =IF(ISNUMBER(SowDate),SowDate-3+44,"") | BF2: =IF(ISNUMBER(SowDate),SowDate-3+45,"") | BG2: =IF(ISNUMBER(SowDate),SowDate-3+46,"") | BH2: =IF(ISNUMBER(SowDate),SowDate-3+47,"") | BI2: =IF(ISNUMBER(SowDate),SowDate-3+48,"") | BJ2: =IF(ISNUMBER(SowDate),SowDate-3+49,"") | BK2: =IF(ISNUMBER(SowDate),SowDate-3+50,"") | BL2: =IF(ISNUMBER(SowDate),SowDate-3+51,"") | BM2: =IF(ISNUMBER(SowDate),SowDate-3+52,"") | BN2: =IF(ISNUMBER(SowDate),SowDate-3+53,"") | BO2: =IF(ISNUMBER(SowDate),SowDate-3+54,"") | BP2: =IF(ISNUMBER(SowDate),SowDate-3+55,"") | BQ2: =IF(ISNUMBER(SowDate),SowDate-3+56,"") | BR2: =IF(ISNUMBER(SowDate),SowDate-3+57,"") | BS2: =IF(ISNUMBER(SowDate),SowDate-3+58,"") | BT2: =IF(ISNUMBER(SowDate),SowDate-3+59,"") | BU2: =IF(ISNUMBER(SowDate),SowDate-3+60,"") | BV2: =IF(ISNUMBER(SowDate),SowDate-3+61,"") | BW2: =IF(ISNUMBER(SowDate),SowDate-3+62,"") | BX2: =IF(ISNUMBER(SowDate),SowDate-3+63,"") | BY2: =IF(ISNUMBER(SowDate),SowDate-3+64,"") | BZ2: =IF(ISNUMBER(SowDate),SowDate-3+65,"") | CA2: =IF(ISNUMBER(SowDate),SowDate-3+66,"") | CB2: =IF(ISNUMBER(SowDate),SowDate-3+67,"") | CC2: =IF(ISNUMBER(SowDate),SowDate-3+68,"") | CD2: =IF(ISNUMBER(SowDate),SowDate-3+69,"") | CE2: =IF(ISNUMBER(SowDate),SowDate-3+70,"") | CF2: =IF(ISNUMBER(SowDate),SowDate-3+71,"") | CG2: =IF(ISNUMBER(SowDate),SowDate-3+72,"") | CH2: =IF(ISNUMBER(SowDate),SowDate-3+73,"") | CI2: =IF(ISNUMBER(SowDate),SowDate-3+74,"") | CJ2: =IF(ISNUMBER(SowDate),SowDate-3+75,"") | CK2: =IF(ISNUMBER(SowDate),SowDate-3+76,"") | CL2: =IF(ISNUMBER(SowDate),SowDate-3+77,"") | CM2: =IF(ISNUMBER(SowDate),SowDate-3+78,"") | CN2: =IF(ISNUMBER(SowDate),SowDate-3+79,"") | CO2: =IF(ISNUMBER(SowDate),SowDate-3+80,"") | CP2: =IF(ISNUMBER(SowDate),SowDate-3+81,"") | CQ2: =IF(ISNUMBER(SowDate),SowDate-3+82,"") | CR2: =IF(ISNUMBER(SowDate),SowDate-3+83,"") | CS2: =IF(ISNUMBER(SowDate),SowDate-3+84,"") | CT2: =IF(ISNUMBER(SowDate),SowDate-3+85,"") | CU2: =IF(ISNUMBER(SowDate),SowDate-3+86,"") | CV2: =IF(ISNUMBER(SowDate),SowDate-3+87,"") | CW2: =IF(ISNUMBER(SowDate),SowDate-3+88,"") | CX2: =IF(ISNUMBER(SowDate),SowDate-3+89,"") | CY2: =IF(ISNUMBER(SowDate),SowDate-3+90,"") | CZ2: =IF(ISNUMBER(SowDate),SowDate-3+91,"") | DA2: =IF(ISNUMBER(SowDate),SowDate-3+92,"") | DB2: =IF(ISNUMBER(SowDate),SowDate-3+93,"") | DC2: =IF(ISNUMBER(SowDate),SowDate-3+94,"") | DD2: =IF(ISNUMBER(SowDate),SowDate-3+95,"") | DE2: =IF(ISNUMBER(SowDate),SowDate-3+96,"") | DF2: =IF(ISNUMBER(SowDate),SowDate-3+97,"") | DG2: =IF(ISNUMBER(SowDate),SowDate-3+98,"") | DH2: =IF(ISNUMBER(SowDate),SowDate-3+99,"") | DI2: =IF(ISNUMBER(SowDate),SowDate-3+100,"") | DJ2: =IF(ISNUMBER(SowDate),SowDate-3+101,"") | DK2: =IF(ISNUMBER(SowDate),SowDate-3+102,"") | DL2: =IF(ISNUMBER(SowDate),SowDate-3+103,"") | DM2: =IF(ISNUMBER(SowDate),SowDate-3+104,"") | DN2: =IF(ISNUMBER(SowDate),SowDate-3+105,"") | DO2: =IF(ISNUMBER(SowDate),SowDate-3+106,"") | DP2: =IF(ISNUMBER(SowDate),SowDate-3+107,"") | DQ2: =IF(ISNUMBER(SowDate),SowDate-3+108,"") | DR2: =IF(ISNUMBER(SowDate),SowDate-3+109,"") | DS2: =IF(ISNUMBER(SowDate),SowDate-3+110,"") | DT2: =IF(ISNUMBER(SowDate),SowDate-3+111,"") | DU2: =IF(ISNUMBER(SowDate),SowDate-3+112,"") | DV2: =IF(ISNUMBER(SowDate),SowDate-3+113,"") | DW2: =IF(ISNUMBER(SowDate),SowDate-3+114,"") | DX2: =IF(ISNUMBER(SowDate),SowDate-3+115,"") | DY2: =IF(ISNUMBER(SowDate),SowDate-3+116,"") | DZ2: =IF(ISNUMBER(SowDate),SowDate-3+117,"") | EA2: =IF(ISNUMBER(SowDate),SowDate-3+118,"") | EB2: =IF(ISNUMBER(SowDate),SowDate-3+119,"") | EC2: =IF(ISNUMBER(SowDate),SowDate-3+120,"") | ED2: =IF(ISNUMBER(SowDate),SowDate-3+121,"") | EE2: =IF(ISNUMBER(SowDate),SowDate-3+122,"") | EF2: =IF(ISNUMBER(SowDate),SowDate-3+123,"") | EG2: =IF(ISNUMBER(SowDate),SowDate-3+124,"") | EH2: =IF(ISNUMBER(SowDate),SowDate-3+125,"") | EI2: =IF(ISNUMBER(SowDate),SowDate-3+126,"") | EJ2: =IF(ISNUMBER(SowDate),SowDate-3+127,"") | EK2: =IF(ISNUMBER(SowDate),SowDate-3+128,"") | EL2: =IF(ISNUMBER(SowDate),SowDate-3+129,"") | EM2: =IF(ISNUMBER(SowDate),SowDate-3+130,"") | EN2: =IF(ISNUMBER(SowDate),SowDate-3+131,"") | EO2: =IF(ISNUMBER(SowDate),SowDate-3+132,"") | EP2: =IF(ISNUMBER(SowDate),SowDate-3+133,"") | EQ2: =IF(ISNUMBER(SowDate),SowDate-3+134,"") | ER2: =IF(ISNUMBER(SowDate),SowDate-3+135,"") | ES2: =IF(ISNUMBER(SowDate),SowDate-3+136,"") | ET2: =IF(ISNUMBER(SowDate),SowDate-3+137,"") | EU2: =IF(ISNUMBER(SowDate),SowDate-3+138,"") | EV2: =IF(ISNUMBER(SowDate),SowDate-3+139,"") | EW2: =IF(ISNUMBER(SowDate),SowDate-3+140,"") | EX2: =IF(ISNUMBER(SowDate),SowDate-3+141,"") | EY2: =IF(ISNUMBER(SowDate),SowDate-3+142,"") | EZ2: =IF(ISNUMBER(SowDate),SowDate-3+143,"") | FA2: =IF(ISNUMBER(SowDate),SowDate-3+144,"") | FB2: =IF(ISNUMBER(SowDate),SowDate-3+145,"") | FC2: =IF(ISNUMBER(SowDate),SowDate-3+146,"") | FD2: =IF(ISNUMBER(SowDate),SowDate-3+147,"") | FE2: =IF(ISNUMBER(SowDate),SowDate-3+148,"") | FF2: =IF(ISNUMBER(SowDate),SowDate-3+149,"") | FG2: =IF(ISNUMBER(SowDate),SowDate-3+150,"") | FH2: =IF(ISNUMBER(SowDate),SowDate-3+151,"") | FI2: =IF(ISNUMBER(SowDate),SowDate-3+152,"") | FJ2: =IF(ISNUMBER(SowDate),SowDate-3+153,"") | FK2: =IF(ISNUMBER(SowDate),SowDate-3+154,"") | FL2: =IF(ISNUMBER(SowDate),SowDate-3+155,"") | FM2: =IF(ISNUMBER(SowDate),SowDate-3+156,"") | FN2: =IF(ISNUMBER(SowDate),SowDate-3+157,"") | FO2: =IF(ISNUMBER(SowDate),SowDate-3+158,"") | FP2: =IF(ISNUMBER(SowDate),SowDate-3+159,"") | FQ2: =IF(ISNUMBER(SowDate),SowDate-3+160,"") | FR2: =IF(ISNUMBER(SowDate),SowDate-3+161,"") | FS2: =IF(ISNUMBER(SowDate),SowDate-3+162,"") | FT2: =IF(ISNUMBER(SowDate),SowDate-3+163,"") | FU2: =IF(ISNUMBER(SowDate),SowDate-3+164,"") | FV2: =IF(ISNUMBER(SowDate),SowDate-3+165,"") | FW2: =IF(ISNUMBER(SowDate),SowDate-3+166,"") | FX2: =IF(ISNUMBER(SowDate),SowDate-3+167,"") | FY2: =IF(ISNUMBER(SowDate),SowDate-3+168,"") | FZ2: =IF(ISNUMBER(SowDate),SowDate-3+169,"") | GA2: =IF(ISNUMBER(SowDate),SowDate-3+170,"") | GB2: =IF(ISNUMBER(SowDate),SowDate-3+171,"") | GC2: =IF(ISNUMBER(SowDate),SowDate-3+172,"") | GD2: =IF(ISNUMBER(SowDate),SowDate-3+173,"") | GE2: =IF(ISNUMBER(SowDate),SowDate-3+174,"")
A3: Event | B3: ঘটনা | C3: Plot | D3: Planned start | E3: Planned end | F3: Actual start | G3: Actual end | H3: Status | I3: Delay (days) | J3: Used start | K3: Used end | L3: next | M3: =IF(M2="","",TEXT(M2,"mmm")) | N3: =IF(N2="","",TEXT(N2,"mmm")) | O3: =IF(O2="","",TEXT(O2,"mmm")) | P3: =IF(P2="","",TEXT(P2,"mmm")) | Q3: =IF(Q2="","",TEXT(Q2,"mmm")) | R3: =IF(R2="","",TEXT(R2,"mmm")) | S3: =IF(S2="","",TEXT(S2,"mmm")) | T3: =IF(T2="","",TEXT(T2,"mmm")) | ... GE3: =IF(GE2="","",TEXT(GE2,"mmm"))
A4: 3F4D+MD plot
A5: Seed wetting | B5: বীজ ভেজানো | C5: 3F4D+MD | E5: =IF(D5="","",D5) | H5: =IF(D5="","no plan",IF(F5<>"",IF(F5-D5>=2,"LATE","OK"),IF(TODAY()>D5+2,"OVERDUE","upcoming"))) | I5: =IF(AND(D5<>"",F5<>""),F5-D5,"") | J5: =IF(F5<>"",F5,D5) | K5: =IF(G5<>"",G5,IF(AND(F5<>"",E5=D5),F5,E5)) | L5: =IF(AND(D5<>"",F5="",D5>=TODAY()),D5+ROW()/1000,"") | M5: =IF(OR(M$2="",$D5=""),"",IF(AND(ISNUMBER($F5),M$2>=$F5,M$2<=IF(ISNUMBER($G5),$G5,$F5+$E5-$D5)),2,IF(AND(M$2>=$D5,M$2<=$E5),1,""))) | N5: =IF(OR(N$2="",$D5=""),"",IF(AND(ISNUMBER($F5),N$2>=$F5,N$2<=IF(ISNUMBER($G5),$G5,$F5+$E5-$D5)),2,IF(AND(N$2>=$D5,N$2<=$E5),1,""))) | O5: =IF(OR(O$2="",$D5=""),"",IF(AND(ISNUMBER($F5),O$2>=$F5,O$2<=IF(ISNUMBER($G5),$G5,$F5+$E5-$D5)),2,IF(AND(O$2>=$D5,O$2<=$E5),1,""))) | P5: =IF(OR(P$2="",$D5=""),"",IF(AND(ISNUMBER($F5),P$2>=$F5,P$2<=IF(ISNUMBER($G5),$G5,$F5+$E5-$D5)),2,IF(AND(P$2>=$D5,P$2<=$E5),1,""))) | Q5: =IF(OR(Q$2="",$D5=""),"",IF(AND(ISNUMBER($F5),Q$2>=$F5,Q$2<=IF(ISNUMBER($G5),$G5,$F5+$E5-$D5)),2,IF(AND(Q$2>=$D5,Q$2<=$E5),1,""))) | R5: =IF(OR(R$2="",$D5=""),"",IF(AND(ISNUMBER($F5),R$2>=$F5,R$2<=IF(ISNUMBER($G5),$G5,$F5+$E5-$D5)),2,IF(AND(R$2>=$D5,R$2<=$E5),1,""))) | S5: =IF(OR(S$2="",$D5=""),"",IF(AND(ISNUMBER($F5),S$2>=$F5,S$2<=IF(ISNUMBER($G5),$G5,$F5+$E5-$D5)),2,IF(AND(S$2>=$D5,S$2<=$E5),1,""))) | T5: =IF(OR(T$2="",$D5=""),"",IF(AND(ISNUMBER($F5),T$2>=$F5,T$2<=IF(ISNUMBER($G5),$G5,$F5+$E5-$D5)),2,IF(AND(T$2>=$D5,T$2<=$E5),1,""))) | ... GE5: =IF(OR(GE$2="",$D5=""),"",IF(AND(ISNUMBER($F5),GE$2>=$F5,GE$2<=IF(ISNUMBER($G5),$G5,$F5+$E5-$D5)),2,IF(AND(GE$2>=$D5,GE$2<=$E5),1,"")))
A6: Sowing | B6: বপন | C6: 3F4D+MD | D6: =IF(ISNUMBER(SowDate),SowDate,"") | E6: =IF(D6="","",D6) | H6: =IF(D6="","no plan",IF(F6<>"",IF(F6-D6>=2,"LATE","OK"),IF(TODAY()>D6+2,"OVERDUE","upcoming"))) | I6: =IF(AND(D6<>"",F6<>""),F6-D6,"") | J6: =IF(F6<>"",F6,D6) | K6: =IF(G6<>"",G6,IF(AND(F6<>"",E6=D6),F6,E6)) | L6: =IF(AND(D6<>"",F6="",D6>=TODAY()),D6+ROW()/1000,"") | M6: =IF(OR(M$2="",$D6=""),"",IF(AND(ISNUMBER($F6),M$2>=$F6,M$2<=IF(ISNUMBER($G6),$G6,$F6+$E6-$D6)),2,IF(AND(M$2>=$D6,M$2<=$E6),1,""))) | N6: =IF(OR(N$2="",$D6=""),"",IF(AND(ISNUMBER($F6),N$2>=$F6,N$2<=IF(ISNUMBER($G6),$G6,$F6+$E6-$D6)),2,IF(AND(N$2>=$D6,N$2<=$E6),1,""))) | O6: =IF(OR(O$2="",$D6=""),"",IF(AND(ISNUMBER($F6),O$2>=$F6,O$2<=IF(ISNUMBER($G6),$G6,$F6+$E6-$D6)),2,IF(AND(O$2>=$D6,O$2<=$E6),1,""))) | P6: =IF(OR(P$2="",$D6=""),"",IF(AND(ISNUMBER($F6),P$2>=$F6,P$2<=IF(ISNUMBER($G6),$G6,$F6+$E6-$D6)),2,IF(AND(P$2>=$D6,P$2<=$E6),1,""))) | Q6: =IF(OR(Q$2="",$D6=""),"",IF(AND(ISNUMBER($F6),Q$2>=$F6,Q$2<=IF(ISNUMBER($G6),$G6,$F6+$E6-$D6)),2,IF(AND(Q$2>=$D6,Q$2<=$E6),1,""))) | R6: =IF(OR(R$2="",$D6=""),"",IF(AND(ISNUMBER($F6),R$2>=$F6,R$2<=IF(ISNUMBER($G6),$G6,$F6+$E6-$D6)),2,IF(AND(R$2>=$D6,R$2<=$E6),1,""))) | S6: =IF(OR(S$2="",$D6=""),"",IF(AND(ISNUMBER($F6),S$2>=$F6,S$2<=IF(ISNUMBER($G6),$G6,$F6+$E6-$D6)),2,IF(AND(S$2>=$D6,S$2<=$E6),1,""))) | T6: =IF(OR(T$2="",$D6=""),"",IF(AND(ISNUMBER($F6),T$2>=$F6,T$2<=IF(ISNUMBER($G6),$G6,$F6+$E6-$D6)),2,IF(AND(T$2>=$D6,T$2<=$E6),1,""))) | ... GE6: =IF(OR(GE$2="",$D6=""),"",IF(AND(ISNUMBER($F6),GE$2>=$F6,GE$2<=IF(ISNUMBER($G6),$G6,$F6+$E6-$D6)),2,IF(AND(GE$2>=$D6,GE$2<=$E6),1,"")))
A7: Plowing | B7: চাষ | C7: 3F4D+MD | E7: =IF(D7="","",D7) | H7: =IF(D7="","no plan",IF(F7<>"",IF(F7-D7>=2,"LATE","OK"),IF(TODAY()>D7+2,"OVERDUE","upcoming"))) | I7: =IF(AND(D7<>"",F7<>""),F7-D7,"") | J7: =IF(F7<>"",F7,D7) | K7: =IF(G7<>"",G7,IF(AND(F7<>"",E7=D7),F7,E7)) | L7: =IF(AND(D7<>"",F7="",D7>=TODAY()),D7+ROW()/1000,"") | M7: =IF(OR(M$2="",$D7=""),"",IF(AND(ISNUMBER($F7),M$2>=$F7,M$2<=IF(ISNUMBER($G7),$G7,$F7+$E7-$D7)),2,IF(AND(M$2>=$D7,M$2<=$E7),1,""))) | N7: =IF(OR(N$2="",$D7=""),"",IF(AND(ISNUMBER($F7),N$2>=$F7,N$2<=IF(ISNUMBER($G7),$G7,$F7+$E7-$D7)),2,IF(AND(N$2>=$D7,N$2<=$E7),1,""))) | O7: =IF(OR(O$2="",$D7=""),"",IF(AND(ISNUMBER($F7),O$2>=$F7,O$2<=IF(ISNUMBER($G7),$G7,$F7+$E7-$D7)),2,IF(AND(O$2>=$D7,O$2<=$E7),1,""))) | P7: =IF(OR(P$2="",$D7=""),"",IF(AND(ISNUMBER($F7),P$2>=$F7,P$2<=IF(ISNUMBER($G7),$G7,$F7+$E7-$D7)),2,IF(AND(P$2>=$D7,P$2<=$E7),1,""))) | Q7: =IF(OR(Q$2="",$D7=""),"",IF(AND(ISNUMBER($F7),Q$2>=$F7,Q$2<=IF(ISNUMBER($G7),$G7,$F7+$E7-$D7)),2,IF(AND(Q$2>=$D7,Q$2<=$E7),1,""))) | R7: =IF(OR(R$2="",$D7=""),"",IF(AND(ISNUMBER($F7),R$2>=$F7,R$2<=IF(ISNUMBER($G7),$G7,$F7+$E7-$D7)),2,IF(AND(R$2>=$D7,R$2<=$E7),1,""))) | S7: =IF(OR(S$2="",$D7=""),"",IF(AND(ISNUMBER($F7),S$2>=$F7,S$2<=IF(ISNUMBER($G7),$G7,$F7+$E7-$D7)),2,IF(AND(S$2>=$D7,S$2<=$E7),1,""))) | T7: =IF(OR(T$2="",$D7=""),"",IF(AND(ISNUMBER($F7),T$2>=$F7,T$2<=IF(ISNUMBER($G7),$G7,$F7+$E7-$D7)),2,IF(AND(T$2>=$D7,T$2<=$E7),1,""))) | ... GE7: =IF(OR(GE$2="",$D7=""),"",IF(AND(ISNUMBER($F7),GE$2>=$F7,GE$2<=IF(ISNUMBER($G7),$G7,$F7+$E7-$D7)),2,IF(AND(GE$2>=$D7,GE$2<=$E7),1,"")))
