Workbook

Sheet Guide
A1: 3F4D Water Monitor - sheet version / শিট সংস্করণ
A2: Water-level record of the FP plot and the 3F4D+MD plot. You enter data in only TWO tabs (yellow tabs). All other tabs are automatic.
A3: মাত্র দুটি ট্যাবে (হলুদ ট্যাব) তথ্য দিন। বাকি সব ট্যাব স্বয়ংক্রিয়।
A5: WHERE TO ENTER / কোথায় লিখবেন
A6: 1_Settings - once at the start of the season: site, sowing date, seedling age, plot area, TP and b, planned dates of seed wetting / plowing / puddling.
A7: 2_Daily_input - every day: one column per day. Tape reading m of both plots (every day), m before and after irrigation, rain and weather, field condition and work. Occasionally: tillers, TP and b measured again, schedule work done, fertilizer and chemicals.
A9: Colours / রং
A10: Yellow cell = enter here. Grey cell = automatic, do not edit. Red cell = needed but still empty. Blue / brown numbers = water above / below the soil surface.
A12: 2_Daily_input - sections from top to bottom
A13: EVERY DAY: m of FP and 3F4D+MD. The water level and the check appear below automatically.
A14: WHEN YOU IRRIGATE: m before and after irrigation (both, on the same day). Irrigation (mm) appears automatically.
A15: WEATHER, FIELD AND WORK, NOTE: when there is something to record.
... A42: Schedule rules follow the 3F4D+MD scheduling app (Professional mode); the numbers of days are in 1_Settings (section E). 3F4D manuals: English https://doi.org/10.5281/zenodo.22932287 , Bengali https://doi.org/10.5281/zenodo.23075395

Sheet 1_Settings
A1: 1 Basic settings / মৌলিক সেটআপ
A2: Enter once at the start of the season, in the YELLOW cells only. Red = required and still empty. Grey = calculated. Daily data go to the tab 2_Daily_input.
A4: A. Site / সাইট
A5: 1 | B5: Site name * / সাইটের নাম | C5: Demo Site-03 | D5: e.g. Chougachha-01
A6: 2 | B6: Place (district / upazila) * / স্থান | C6: Pirganj, Rangpur | D6: e.g. Chougachha, Jashore
A7: 3 | B7: Latitude (optional) | C7: 23.1 | D7: e.g. 23.27
A8: 4 | B8: Longitude (optional) | C8: 89 | D8: e.g. 89.25
A9: 5 | B9: Variety / জাত | C9: BRRI dhan58 | D9: e.g. Rod miniket
A11: B. Crop dates / তারিখ
A12: 6 | B12: Sowing date (seedbed) * / বপনের তারিখ | C12: 45989 | D12: e.g. 02 Dec 2025
A13: 7 | B13: Seedling age at transplanting (days) * / চারার বয়স | C13: 49 | D13: e.g. 49
B14: Transplanting date (automatic) / রোপণের তারিখ | C14: =IF(AND(ISNUMBER(C12),ISNUMBER(C13)),C12+C13,"") -> 46038 | D14: sowing date + seedling age
B15: Day 0 of the schedule (automatic) | C15: =IF(C14="","",C14-35) -> 46003 | D15: transplanting date - 35 (same as the 3F4D+MD scheduling app)
A16: 8 | B16: First date of the daily sheet (optional) | D16: Leave empty = 3 days before sowing (seed wetting). Do not change it after data entry has started.
B17: First date used (automatic) | C17: =IF(ISNUMBER(C16),C16,IF(ISNUMBER(C12),C12-3,"")) -> 45986
A19: C. Plots: area and the water-level pipe / প্লট
B20: Plot / প্লট | C20: Plot ID | D20: Area (decimal) * | E20: TP (cm) * | F20: b (cm) * | G20: Area (m2, auto) | H20: TP = tape reading at the top of the pipe; b = height of the pipe top above the soil (see How_to_measure)
A21: 9 | B21: FP (farmers practice) | C21: FP-1 | D21: 8.457 | E21: 295 | F21: 16 | G21: =IF(ISNUMBER(D21),D21*40.4686,"") -> 342.24295
A22: 10 | B22: 3F4D+MD | C22: MD-1 | D22: 8.457 | E22: 415 | F22: 16 | G22: =IF(ISNUMBER(D22),D22*40.4686,"") -> 342.24295
A23: 11 | B23: Date TP and b were measured / TP ও b মাপার তারিখ | C23: 46038 | D23: Usually the transplanting day. Later re-measurements (after Pitan / MD): enter them in 2_Daily_input.
A25: D. Planned dates you decide yourself / নিজে ঠিক করা তারিখ
A26: 12 | B26: Seed wetting - planned date | C26: 45986 | D26: The other planned dates are calculated (Schedule_Farmer).
A27: 13 | B27: Plowing - planned date | C27: 45995
A28: 14 | B28: Puddling - planned date | C28: 46025
A30: E. Schedule rules (days) - usually do not change / সাধারণত পরিবর্তন করবেন না
B31: Days from sowing to transplanting (app) | C31: 35
B32: Pitan start: days after transplanting | C32: 30
B33: Pitan duration (days) | C33: 3
B34: MD start: days after sowing (app) | C34: 66
B35: MD duration (days) | C35: 8
B36: PI check: days after MD start | C36: 6
B37: Heading: days after sowing (app) | C37: 111
B38: Flooding before heading (days) | C38: 25
B39: 3F4D start before heading (days) | C39: 21
B40: Harvest: days after heading | C40: 28
B41: FP: Pitan duration (days) | C41: 8
B42: FP: last irrigation, days before harvest | C42: 15
... B44: 3F4D cycle length (days; 8 if one day was lost) | C44: 7
A46: F. N and P content of fertilizers (fraction) - usually do not change
B47: Fertilizer | C47: N (fraction) | D47: P (fraction)
...

Sheet 2_Daily_input
B1: 2 Daily input / দৈনিক তথ্য | C1: Date | D1: =IF(ISNUMBER(DataStart),DataStart+0,"") -> 45986 | E1: =IF(ISNUMBER(DataStart),DataStart+1,"") -> 45987 | F1: =IF(ISNUMBER(DataStart),DataStart+2,"") -> 45988 | G1: =IF(ISNUMBER(DataStart),DataStart+3,"") -> 45989 | H1: =IF(ISNUMBER(DataStart),DataStart+4,"") -> 45990 | I1: =IF(ISNUMBER(DataStart),DataStart+5,"") -> 45991 | J1: =IF(ISNUMBER(DataStart),DataStart+6,"") -> 45992 | K1: =IF(ISNUMBER(DataStart),DataStart+7,"") -> 45993 | L1: =IF(ISNUMBER(DataStart),DataStart+8,"") -> 45994 | M1: =IF(ISNUMBER(DataStart),DataStart+9,"") -> 45995 | N1: =IF(ISNUMBER(DataStart),DataStart+10,"") -> 45996 | O1: =IF(ISNUMBER(DataStart),DataStart+11,"") -> 45997 | P1: =IF(ISNUMBER(DataStart),DataStart+12,"") -> 45998 | Q1: =IF(ISNUMBER(DataStart),DataStart+13,"") -> 45999 | R1: =IF(ISNUMBER(DataStart),DataStart+14,"") -> 46000 | S1: =IF(ISNUMBER(DataStart),DataStart+15,"") -> 46001 | T1: =IF(ISNUMBER(DataStart),DataStart+16,"") -> 46002 | U1: =IF(ISNUMBER(DataStart),DataStart+17,"") -> 46003 | V1: =IF(ISNUMBER(DataStart),DataStart+18,"") -> 46004 | W1: =IF(ISNUMBER(DataStart),DataStart+19,"") -> 46005 | X1: =IF(ISNUMBER(DataStart),DataStart+20,"") -> 46006 | Y1: =IF(ISNUMBER(DataStart),DataStart+21,"") -> 46007 | Z1: =IF(ISNUMBER(DataStart),DataStart+22,"") -> 46008 | AA1: =IF(ISNUMBER(DataStart),DataStart+23,"") -> 46009 | AB1: =IF(ISNUMBER(DataStart),DataStart+24,"") -> 46010 | AC1: =IF(ISNUMBER(DataStart),DataStart+25,"") -> 46011 | AD1: =IF(ISNUMBER(DataStart),DataStart+26,"") -> 46012 | AE1: =IF(ISNUMBER(DataStart),DataStart+27,"") -> 46013 | AF1: =IF(ISNUMBER(DataStart),DataStart+28,"") -> 46014 | AG1: =IF(ISNUMBER(DataStart),DataStart+29,"") -> 46015 | AH1: =IF(ISNUMBER(DataStart),DataStart+30,"") -> 46016 | AI1: =IF(ISNUMBER(DataStart),DataStart+31,"") -> 46017 | AJ1: =IF(ISNUMBER(DataStart),DataStart+32,"") -> 46018 | AK1: =IF(ISNUMBER(DataStart),DataStart+33,"") -> 46019 | AL1: =IF(ISNUMBER(DataStart),DataStart+34,"") -> 46020 | AM1: =IF(ISNUMBER(DataStart),DataStart+35,"") -> 46021 | AN1: =IF(ISNUMBER(DataStart),DataStart+36,"") -> 46022 | AO1: =IF(ISNUMBER(DataStart),DataStart+37,"") -> 46023 | AP1: =IF(ISNUMBER(DataStart),DataStart+38,"") -> 46024 | AQ1: =IF(ISNUMBER(DataStart),DataStart+39,"") -> 46025 | AR1: =IF(ISNUMBER(DataStart),DataStart+40,"") -> 46026 | AS1: =IF(ISNUMBER(DataStart),DataStart+41,"") -> 46027 | AT1: =IF(ISNUMBER(DataStart),DataStart+42,"") -> 46028 | AU1: =IF(ISNUMBER(DataStart),DataStart+43,"") -> 46029 | AV1: =IF(ISNUMBER(DataStart),DataStart+44,"") -> 46030 | AW1: =IF(ISNUMBER(DataStart),DataStart+45,"") -> 46031 | AX1: =IF(ISNUMBER(DataStart),DataStart+46,"") -> 46032 | AY1: =IF(ISNUMBER(DataStart),DataStart+47,"") -> 46033 | AZ1: =IF(ISNUMBER(DataStart),DataStart+48,"") -> 46034 | BA1: =IF(ISNUMBER(DataStart),DataStart+49,"") -> 46035 | BB1: =IF(ISNUMBER(DataStart),DataStart+50,"") -> 46036 | BC1: =IF(ISNUMBER(DataStart),DataStart+51,"") -> 46037 | BD1: =IF(ISNUMBER(DataStart),DataStart+52,"") -> 46038 | BE1: =IF(ISNUMBER(DataStart),DataStart+53,"") -> 46039 | BF1: =IF(ISNUMBER(DataStart),DataStart+54,"") -> 46040 | BG1: =IF(ISNUMBER(DataStart),DataStart+55,"") -> 46041 | BH1: =IF(ISNUMBER(DataStart),DataStart+56,"") -> 46042 | BI1: =IF(ISNUMBER(DataStart),DataStart+57,"") -> 46043 | BJ1: =IF(ISNUMBER(DataStart),DataStart+58,"") -> 46044 | BK1: =IF(ISNUMBER(DataStart),DataStart+59,"") -> 46045 | BL1: =IF(ISNUMBER(DataStart),DataStart+60,"") -> 46046 | BM1: =IF(ISNUMBER(DataStart),DataStart+61,"") -> 46047 | BN1: =IF(ISNUMBER(DataStart),DataStart+62,"") -> 46048 | BO1: =IF(ISNUMBER(DataStart),DataStart+63,"") -> 46049 | BP1: =IF(ISNUMBER(DataStart),DataStart+64,"") -> 46050 | BQ1: =IF(ISNUMBER(DataStart),DataStart+65,"") -> 46051 | BR1: =IF(ISNUMBER(DataStart),DataStart+66,"") -> 46052 | BS1: =IF(ISNUMBER(DataStart),DataStart+67,"") -> 46053 | BT1: =IF(ISNUMBER(DataStart),DataStart+68,"") -> 46054 | BU1: =IF(ISNUMBER(DataStart),DataStart+69,"") -> 46055 | BV1: =IF(ISNUMBER(DataStart),DataStart+70,"") -> 46056 | BW1: =IF(ISNUMBER(DataStart),DataStart+71,"") -> 46057 | BX1: =IF(ISNUMBER(DataStart),DataStart+72,"") -> 46058 | BY1: =IF(ISNUMBER(DataStart),DataStart+73,"") -> 46059 | BZ1: =IF(ISNUMBER(DataStart),DataStart+74,"") -> 46060 | CA1: =IF(ISNUMBER(DataStart),DataStart+75,"") -> 46061 | CB1: =IF(ISNUMBER(DataStart),DataStart+76,"") -> 46062 | CC1: =IF(ISNUMBER(DataStart),DataStart+77,"") -> 46063 | CD1: =IF(ISNUMBER(DataStart),DataStart+78,"") -> 46064 | CE1: =IF(ISNUMBER(DataStart),DataStart+79,"") -> 46065 | CF1: =IF(ISNUMBER(DataStart),DataStart+80,"") -> 46066 | CG1: =IF(ISNUMBER(DataStart),DataStart+81,"") -> 46067 | CH1: =IF(ISNUMBER(DataStart),DataStart+82,"") -> 46068 | CI1: =IF(ISNUMBER(DataStart),DataStart+83,"") -> 46069 | CJ1: =IF(ISNUMBER(DataStart),DataStart+84,"") -> 46070 | CK1: =IF(ISNUMBER(DataStart),DataStart+85,"") -> 46071 | CL1: =IF(ISNUMBER(DataStart),DataStart+86,"") -> 46072 | CM1: =IF(ISNUMBER(DataStart),DataStart+87,"") -> 46073 | CN1: =IF(ISNUMBER(DataStart),DataStart+88,"") -> 46074 | CO1: =IF(ISNUMBER(DataStart),DataStart+89,"") -> 46075 | CP1: =IF(ISNUMBER(DataStart),DataStart+90,"") -> 46076 | CQ1: =IF(ISNUMBER(DataStart),DataStart+91,"") -> 46077 | CR1: =IF(ISNUMBER(DataStart),DataStart+92,"") -> 46078 | CS1: =IF(ISNUMBER(DataStart),DataStart+93,"") -> 46079 | CT1: =IF(ISNUMBER(DataStart),DataStart+94,"") -> 46080 | CU1: =IF(ISNUMBER(DataStart),DataStart+95,"") -> 46081 | CV1: =IF(ISNUMBER(DataStart),DataStart+96,"") -> 46082 | CW1: =IF(ISNUMBER(DataStart),DataStart+97,"") -> 46083 | CX1: =IF(ISNUMBER(DataStart),DataStart+98,"") -> 46084 | CY1: =IF(ISNUMBER(DataStart),DataStart+99,"") -> 46085 | CZ1: =IF(ISNUMBER(DataStart),DataStart+100,"") -> 46086 | DA1: =IF(ISNUMBER(DataStart),DataStart+101,"") -> 46087 | DB1: =IF(ISNUMBER(DataStart),DataStart+102,"") -> 46088 | DC1: =IF(ISNUMBER(DataStart),DataStart+103,"") -> 46089 | DD1: =IF(ISNUMBER(DataStart),DataStart+104,"") -> 46090 | DE1: =IF(ISNUMBER(DataStart),DataStart+105,"") -> 46091 | DF1: =IF(ISNUMBER(DataStart),DataStart+106,"") -> 46092 | DG1: =IF(ISNUMBER(DataStart),DataStart+107,"") -> 46093 | DH1: =IF(ISNUMBER(DataStart),DataStart+108,"") -> 46094 | DI1: =IF(ISNUMBER(DataStart),DataStart+109,"") -> 46095 | DJ1: =IF(ISNUMBER(DataStart),DataStart+110,"") -> 46096 | DK1: =IF(ISNUMBER(DataStart),DataStart+111,"") -> 46097 | DL1: =IF(ISNUMBER(DataStart),DataStart+112,"") -> 46098 | DM1: =IF(ISNUMBER(DataStart),DataStart+113,"") -> 46099 | DN1: =IF(ISNUMBER(DataStart),DataStart+114,"") -> 46100 | DO1: =IF(ISNUMBER(DataStart),DataStart+115,"") -> 46101 | DP1: =IF(ISNUMBER(DataStart),DataStart+116,"") -> 46102 | DQ1: =IF(ISNUMBER(DataStart),DataStart+117,"") -> 46103 | DR1: =IF(ISNUMBER(DataStart),DataStart+118,"") -> 46104 | DS1: =IF(ISNUMBER(DataStart),DataStart+119,"") -> 46105 | DT1: =IF(ISNUMBER(DataStart),DataStart+120,"") -> 46106 | DU1: =IF(ISNUMBER(DataStart),DataStart+121,"") -> 46107 | DV1: =IF(ISNUMBER(DataStart),DataStart+122,"") -> 46108 | DW1: =IF(ISNUMBER(DataStart),DataStart+123,"") -> 46109 | DX1: =IF(ISNUMBER(DataStart),DataStart+124,"") -> 46110 | DY1: =IF(ISNUMBER(DataStart),DataStart+125,"") -> 46111 | DZ1: =IF(ISNUMBER(DataStart),DataStart+126,"") -> 46112 | EA1: =IF(ISNUMBER(DataStart),DataStart+127,"") -> 46113 | EB1: =IF(ISNUMBER(DataStart),DataStart+128,"") -> 46114 | EC1: =IF(ISNUMBER(DataStart),DataStart+129,"") -> 46115 | ED1: =IF(ISNUMBER(DataStart),DataStart+130,"") -> 46116 | EE1: =IF(ISNUMBER(DataStart),DataStart+131,"") -> 46117 | EF1: =IF(ISNUMBER(DataStart),DataStart+132,"") -> 46118 | EG1: =IF(ISNUMBER(DataStart),DataStart+133,"") -> 46119 | EH1: =IF(ISNUMBER(DataStart),DataStart+134,"") -> 46120 | EI1: =IF(ISNUMBER(DataStart),DataStart+135,"") -> 46121 | EJ1: =IF(ISNUMBER(DataStart),DataStart+136,"") -> 46122 | EK1: =IF(ISNUMBER(DataStart),DataStart+137,"") -> 46123 | EL1: =IF(ISNUMBER(DataStart),DataStart+138,"") -> 46124 | EM1: =IF(ISNUMBER(DataStart),DataStart+139,"") -> 46125 | EN1: =IF(ISNUMBER(DataStart),DataStart+140,"") -> 46126 | EO1: =IF(ISNUMBER(DataStart),DataStart+141,"") -> 46127 | EP1: =IF(ISNUMBER(DataStart),DataStart+142,"") -> 46128 | EQ1: =IF(ISNUMBER(DataStart),DataStart+143,"") -> 46129 | ER1: =IF(ISNUMBER(DataStart),DataStart+144,"") -> 46130 | ES1: =IF(ISNUMBER(DataStart),DataStart+145,"") -> 46131 | ET1: =IF(ISNUMBER(DataStart),DataStart+146,"") -> 46132 | EU1: =IF(ISNUMBER(DataStart),DataStart+147,"") -> 46133 | EV1: =IF(ISNUMBER(DataStart),DataStart+148,"") -> 46134 | EW1: =IF(ISNUMBER(DataStart),DataStart+149,"") -> 46135 | EX1: =IF(ISNUMBER(DataStart),DataStart+150,"") -> 46136 | EY1: =IF(ISNUMBER(DataStart),DataStart+151,"") -> 46137 | EZ1: =IF(ISNUMBER(DataStart),DataStart+152,"") -> 46138 | FA1: =IF(ISNUMBER(DataStart),DataStart+153,"") -> 46139 | FB1: =IF(ISNUMBER(DataStart),DataStart+154,"") -> 46140 | FC1: =IF(ISNUMBER(DataStart),DataStart+155,"") -> 46141 | FD1: =IF(ISNUMBER(DataStart),DataStart+156,"") -> 46142 | FE1: =IF(ISNUMBER(DataStart),DataStart+157,"") -> 46143 | FF1: =IF(ISNUMBER(DataStart),DataStart+158,"") -> 46144 | FG1: =IF(ISNUMBER(DataStart),DataStart+159,"") -> 46145 | FH1: =IF(ISNUMBER(DataStart),DataStart+160,"") -> 46146 | FI1: =IF(ISNUMBER(DataStart),DataStart+161,"") -> 46147 | FJ1: =IF(ISNUMBER(DataStart),DataStart+162,"") -> 46148 | FK1: =IF(ISNUMBER(DataStart),DataStart+163,"") -> 46149 | FL1: =IF(ISNUMBER(DataStart),DataStart+164,"") -> 46150 | FM1: =IF(ISNUMBER(DataStart),DataStart+165,"") -> 46151 | FN1: =IF(ISNUMBER(DataStart),DataStart+166,"") -> 46152 | FO1: =IF(ISNUMBER(DataStart),DataStart+167,"") -> 46153 | FP1: =IF(ISNUMBER(DataStart),DataStart+168,"") -> 46154 | FQ1: =IF(ISNUMBER(DataStart),DataStart+169,"") -> 46155
B2: One column per day. Enter in the YELLOW cells only. | C2: Weekday | D2: =IF(D1="","",TEXT(D1,"ddd")) -> Tue | E2: =IF(E1="","",TEXT(E1,"ddd")) -> Wed | F2: =IF(F1="","",TEXT(F1,"ddd")) -> Thu | G2: =IF(G1="","",TEXT(G1,"ddd")) -> Fri | H2: =IF(H1="","",TEXT(H1,"ddd")) -> Sat | I2: =IF(I1="","",TEXT(I1,"ddd")) -> Sun | J2: =IF(J1="","",TEXT(J1,"ddd")) -> Mon | K2: =IF(K1="","",TEXT(K1,"ddd")) -> Tue | ... FQ2: =IF(FQ1="","",TEXT(FQ1,"ddd")) -> Wed
B3: =IFERROR("Today: column "&SUBSTITUTE(ADDRESS(1,MATCH(TODAY(),$D$1:$FQ$1,0)+3,4),"1",""),"Today is outside the dates of this sheet") -> Today is outside the dates of this sheet | C3: Days after transplanting | D3: =IF(OR(D1="",NOT(ISNUMBER(TransDate))),"",D1-TransDate) -> -52 | E3: =IF(OR(E1="",NOT(ISNUMBER(TransDate))),"",E1-TransDate) -> -51 | F3: =IF(OR(F1="",NOT(ISNUMBER(TransDate))),"",F1-TransDate) -> -50 | G3: =IF(OR(G1="",NOT(ISNUMBER(TransDate))),"",G1-TransDate) -> -49 | H3: =IF(OR(H1="",NOT(ISNUMBER(TransDate))),"",H1-TransDate) -> -48 | I3: =IF(OR(I1="",NOT(ISNUMBER(TransDate))),"",I1-TransDate) -> -47 | J3: =IF(OR(J1="",NOT(ISNUMBER(TransDate))),"",J1-TransDate) -> -46 | K3: =IF(OR(K1="",NOT(ISNUMBER(TransDate))),"",K1-TransDate) -> -45 | ... FQ3: =IF(OR(FQ1="",NOT(ISNUMBER(TransDate))),"",FQ1-TransDate) -> 117
B4: Red cell = needed but empty. Grey = automatic. | C4: Stage (schedule) | D4: =Data_Farmer!D6 | E4: =Data_Farmer!E6 | F4: =Data_Farmer!F6 | G4: =Data_Farmer!G6 | H4: =Data_Farmer!H6 | I4: =Data_Farmer!I6 | J4: =Data_Farmer!J6 | K4: =Data_Farmer!K6 | ... FQ4: =Data_Farmer!FQ6
B6: EVERY DAY: tape reading m at the pipe / প্রতিদিন: পাইপে টেপের মাপ m
B7: FP: m (cm) * | C7: every day | BD7: 280 | BE7: 279.9 | BF7: 280.5 | BG7: 280 | BH7: 282.1 | BI7: 281.4 | BJ7: 281.2 | BK7: 280.5 | BL7: 281.8 | BM7: 281.5 | BN7: 281.1 | BO7: 280.5 | BP7: 280.3 | BQ7: 281.5 | BR7: 281.1 | BS7: 280.4 | BT7: 280.2 | BU7: 280 | BV7: 279.9 | BW7: 279.7 | BX7: 281.6 | BY7: 281.4 | BZ7: 280.9 | CB7: 280.1 | CC7: 279.5 | CD7: 278.5 | CE7: 281 | CF7: 280.5 | CG7: 280.3 | CH7: 279.9 | CI7: 282.8 | CJ7: 282.3 | CK7: 281.5 | CL7: 280 | CM7: 279.7 | CN7: 279 | CO7: 277 | CP7: 275 | CQ7: 272 | CR7: 265 | CS7: 265 | CT7: 265 | CU7: 265 | CV7: 265 | CW7: 265 | CX7: 281 | CY7: 280.7 | CZ7: 280.2 | DA7: 281.7 | DB7: 281 | DC7: 280.5 | DD7: 282.5 | DE7: 282 | DF7: 281.5 | DG7: 281 | DH7: 280.7 | DI7: 280.1 | DJ7: 280 | DK7: 281 | DM7: 280.2 | DN7: 280.9 | DO7: 280 | DP7: 281 | DQ7: 280.7 | DR7: 280.3 | DS7: 280.5 | DT7: 280 | DU7: 281 | DV7: 280.7 | DW7: 280.5 | DX7: 281 | DY7: 280.7 | DZ7: 280.5 | EA7: 280.1 | EB7: 281.5 | EC7: 281 | ED7: 280.7 | EE7: 282 | EF7: 281.7 | EG7: 281 | EH7: 280.6 | EI7: 281.5 | EJ7: 281 | EK7: 282.5 | EL7: 281.5 | EM7: 282.5 | EN7: 282 | EO7: 281.5 | EP7: 280.5 | EQ7: 281.5 | ER7: 280 | ES7: 273.5 | ET7: 265
B8: 3F4D+MD: m (cm) * | C8: every day | BD8: 400.3 | BE8: 400 | BF8: 400.3 | BG8: 400 | BH8: 402.2 | BI8: 401.3 | BJ8: 401.1 | BK8: 400.5 | BL8: 402 | BM8: 401.5 | BN8: 401 | BO8: 400.5 | BP8: 400.3 | BQ8: 401.5 | BR8: 401 | BS8: 400.5 | BT8: 400.3 | BU8: 400.1 | BV8: 400 | BW8: 399.5 | BX8: 401.3 | BY8: 401 | BZ8: 400.5 | CB8: 400 | CC8: 398.8 | CD8: 398.3 | CE8: 401 | CF8: 400.7 | CG8: 400.5 | CH8: 400 | CI8: 402.8 | CJ8: 402.2 | CK8: 401.5 | CL8: 400 | CM8: 399.7 | CN8: 399 | CO8: 395 | CP8: 392 | CQ8: 385 | CR8: 385 | CS8: 385 | CT8: 385 | CU8: 385 | CV8: 385 | CW8: 385 | CX8: 401 | CY8: 400.7 | CZ8: 400.2 | DA8: 401.7 | DB8: 401 | DC8: 400.5 | DD8: 401.6 | DE8: 401 | DF8: 400.7 | DG8: 400.3 | DH8: 400.8 | DI8: 400.4 | DJ8: 397 | DK8: 394 | DM8: 389 | DN8: 388 | DO8: 401 | DP8: 400.5 | DQ8: 396 | DR8: 391 | DS8: 388 | DT8: 385 | DU8: 385 | DV8: 401 | DW8: 400.5 | DX8: 398 | DY8: 393 | DZ8: 388 | EA8: 385 | EB8: 385 | EC8: 401.5 | ED8: 400.3 | EE8: 402 | EF8: 399 | EG8: 394.3 | EH8: 389 | EI8: 386 | EJ8: 385 | EK8: 403 | EL8: 402 | EM8: 403 | EN8: 402 | EO8: 400 | EP8: 397 | EQ8: 390 | ER8: 385 | ES8: 385 | ET8: 385
B9: FP: water level (cm) | C9: automatic | D9: =IF(Data_Farmer!D13="","",Data_Farmer!D13) | E9: =IF(Data_Farmer!E13="","",Data_Farmer!E13) | F9: =IF(Data_Farmer!F13="","",Data_Farmer!F13) | G9: =IF(Data_Farmer!G13="","",Data_Farmer!G13) | H9: =IF(Data_Farmer!H13="","",Data_Farmer!H13) | I9: =IF(Data_Farmer!I13="","",Data_Farmer!I13) | J9: =IF(Data_Farmer!J13="","",Data_Farmer!J13) | K9: =IF(Data_Farmer!K13="","",Data_Farmer!K13) | ... FQ9: =IF(Data_Farmer!FQ13="","",Data_Farmer!FQ13)
B10: 3F4D+MD: water level (cm) | C10: automatic | D10: =IF(Data_Farmer!D38="","",Data_Farmer!D38) | E10: =IF(Data_Farmer!E38="","",Data_Farmer!E38) | F10: =IF(Data_Farmer!F38="","",Data_Farmer!F38) | G10: =IF(Data_Farmer!G38="","",Data_Farmer!G38) | H10: =IF(Data_Farmer!H38="","",Data_Farmer!H38) | I10: =IF(Data_Farmer!I38="","",Data_Farmer!I38) | J10: =IF(Data_Farmer!J38="","",Data_Farmer!J38) | K10: =IF(Data_Farmer!K38="","",Data_Farmer!K38) | ... FQ10: =IF(Data_Farmer!FQ38="","",Data_Farmer!FQ38)
B11: FP: input check (automatic) | C11: warnings, see Guide | D11: =IF(Data_Farmer!D30="","",Data_Farmer!D30) | E11: =IF(Data_Farmer!E30="","",Data_Farmer!E30) | F11: =IF(Data_Farmer!F30="","",Data_Farmer!F30) | G11: =IF(Data_Farmer!G30="","",Data_Farmer!G30) | H11: =IF(Data_Farmer!H30="","",Data_Farmer!H30) | I11: =IF(Data_Farmer!I30="","",Data_Farmer!I30) | J11: =IF(Data_Farmer!J30="","",Data_Farmer!J30) | K11: =IF(Data_Farmer!K30="","",Data_Farmer!K30) | ... FQ11: =IF(Data_Farmer!FQ30="","",Data_Farmer!FQ30)
B12: 3F4D+MD: input check (automatic) | C12: warnings, see Guide | D12: =IF(Data_Farmer!D55="","",Data_Farmer!D55) | E12: =IF(Data_Farmer!E55="","",Data_Farmer!E55) | F12: =IF(Data_Farmer!F55="","",Data_Farmer!F55) | G12: =IF(Data_Farmer!G55="","",Data_Farmer!G55) | H12: =IF(Data_Farmer!H55="","",Data_Farmer!H55) | I12: =IF(Data_Farmer!I55="","",Data_Farmer!I55) | J12: =IF(Data_Farmer!J55="","",Data_Farmer!J55) | K12: =IF(Data_Farmer!K55="","",Data_Farmer!K55) | ... FQ12: =IF(Data_Farmer!FQ55="","",Data_Farmer!FQ55)
B14: WHEN YOU IRRIGATE: m before and after irrigation / সেচ দিলে
B15: FP: m before irrigation (cm) | C15: only on irrigation days | BE15: 279.9 | BG15: 280 | BK15: 280.5 | BP15: 280.3 | BW15: 279.7 | CD15: 278.5 | CH15: 279.9 | CW15: 265 | CZ15: 280.2 | DC15: 280.5 | DI15: 280.1 | DJ15: 280 | DM15: 280.2 | DO15: 280 | DR15: 280.3 | DT15: 280 | DW15: 280.5 | EA15: 280.1 | EH15: 280.6 | EJ15: 281 | EP15: 280.5
B16: FP: m after irrigation (cm) | C16: only on irrigation days | BE16: 280.6 | BG16: 282.4 | BK16: 282.3 | BP16: 281.9 | BW16: 282.4 | CD16: 281.3 | CH16: 282.8 | CW16: 280.7 | CZ16: 281.9 | DC16: 283.4 | DI16: 282.4 | DJ16: 281.9 | DM16: 281 | DO16: 281.9 | DR16: 281 | DT16: 281.9 | DW16: 281.9 | EA16: 282.1 | EH16: 281.9 | EJ16: 283.4 | EP16: 281.9
B17: FP: irrigation time (min:sec) | C17: optional | BE17: 15:00 | BG17: 40:00 | BK17: 40:00 | BP17: 30:00 | BW17: 20:00 | CD17: 25:00 | CH17: 40:00 | CW17: 30:00 | CZ17: 30:00 | DC17: 40:00 | DI17: 20:00 | DJ17: 20:00 | DM17: 10:00 | DO17: 20:00 | DR17: 20:00 | DT17: 30:00 | DW17: 20:00 | EA17: 20:00 | EH17: 25:00 | EJ17: 25:00 | EP17: 20:00
B18: 3F4D+MD: m before irrigation (cm) | C18: only on irrigation days | BE18: 400 | BG18: 400 | BK18: 400.5 | BP18: 400.3 | BW18: 399.5 | CD18: 398.3 | CH18: 400 | CW18: 385 | CZ18: 400.2 | DC18: 400.5 | DG18: 400.3 | DN18: 388 | DU18: 385 | EB18: 385 | EJ18: 385
B19: 3F4D+MD: m after irrigation (cm) | C19: only on irrigation days | BE19: 400.5 | BG19: 402.4 | BK19: 402.3 | BP19: 401.9 | BW19: 401.4 | CD19: 401.2 | CH19: 402.9 | CW19: 401 | CZ19: 401.9 | DC19: 402.6 | DG19: 401.3 | DN19: 401.1 | DU19: 401.5 | EB19: 401.5 | EJ19: 403.9
B20: 3F4D+MD: irrigation time (min:sec) | C20: optional | BE20: 15:00 | BG20: 40:00 | BK20: 40:00 | BP20: 30:00 | BW20: 20:00 | CD20: 25:00 | CH20: 40:00 | CW20: 30:00 | CZ20: 30:00 | DC20: 40:00 | DG20: 20:00 | DN20: 20:00 | DU20: 30:00 | EB20: 30:00 | EJ20: 35:00
B21: FP: irrigation (mm) | C21: automatic | D21: =IF(Data_Farmer!D21="","",Data_Farmer!D21) | E21: =IF(Data_Farmer!E21="","",Data_Farmer!E21) | F21: =IF(Data_Farmer!F21="","",Data_Farmer!F21) | G21: =IF(Data_Farmer!G21="","",Data_Farmer!G21) | H21: =IF(Data_Farmer!H21="","",Data_Farmer!H21) | I21: =IF(Data_Farmer!I21="","",Data_Farmer!I21) | J21: =IF(Data_Farmer!J21="","",Data_Farmer!J21) | K21: =IF(Data_Farmer!K21="","",Data_Farmer!K21) | ... FQ21: =IF(Data_Farmer!FQ21="","",Data_Farmer!FQ21)
B22: 3F4D+MD: irrigation (mm) | C22: automatic | D22: =IF(Data_Farmer!D46="","",Data_Farmer!D46) | E22: =IF(Data_Farmer!E46="","",Data_Farmer!E46) | F22: =IF(Data_Farmer!F46="","",Data_Farmer!F46) | G22: =IF(Data_Farmer!G46="","",Data_Farmer!G46) | H22: =IF(Data_Farmer!H46="","",Data_Farmer!H46) | I22: =IF(Data_Farmer!I46="","",Data_Farmer!I46) | J22: =IF(Data_Farmer!J46="","",Data_Farmer!J46) | K22: =IF(Data_Farmer!K46="","",Data_Farmer!K46) | ... FQ22: =IF(Data_Farmer!FQ46="","",Data_Farmer!FQ46)
B24: WEATHER (both plots) / আবহাওয়া
B25: Rain fall (mm) / বৃষ্টি | C25: if it rained | CM25: 3.2 | DO25: 7.3 | DU25: 2.1 | EB25: 7.3 | EC25: 2 | ED25: 1.1 | EE25: 21.1 | EM25: 15.8
B26: Temperature (°C) | C26: optional | BD26: 25 | BE26: 25 | BF26: 23 | BG26: 20 | BH26: 17 | BI26: 23 | BJ26: 22 | BK26: 21 | BL26: 23 | BM26: 19 | BN26: 24 | BO26: 24 | BP26: 24 | BQ26: 23 | BR26: 17 | BS26: 24 | BT26: 24 | BU26: 23 | BV26: 24 | BW26: 21 | BX26: 25 | BY26: 19 | BZ26: 25 | CB26: 23 | CC26: 24 | CD26: 24 | CE26: 20 | CF26: 18 | CG26: 21 | CH26: 21 | CI26: 25 | CJ26: 28 | CK26: 24 | CL26: 24 | CM26: 23 | CN26: 27 | CO26: 28 | CP26: 21 | CQ26: 21 | CR26: 22 | CS26: 26 | CT26: 30 | CU26: 31 | CV26: 24 | CW26: 28 | CX26: 29 | CY26: 31 | CZ26: 29 | DA26: 29 | DB26: 31 | DC26: 28 | DD26: 31 | DE26: 33 | DF26: 26 | DG26: 32 | DH26: 33 | DI26: 31 | DJ26: 29 | DK26: 31 | DM26: 23 | DN26: 28 | DO26: 31 | DP26: 28 | DQ26: 32 | DR26: 24 | DS26: 23 | DT26: 22 | DU26: 32 | DV26: 29 | DW26: 28 | DX26: 34 | DY26: 37 | DZ26: 36 | EA26: 34 | EB26: 33 | EC26: 31 | ED26: 29 | EE26: 24 | EF26: 31 | EG26: 32 | EH26: 33 | EI26: 34 | EJ26: 35 | EK26: 35 | EL26: 33 | EM26: 31 | EN26: 34 | EO26: 35 | EP26: 37 | EQ26: 36 | ER26: 36 | ES26: 37 | ET26: 32
B27: Humidity (%) | C27: optional | BD27: 49 | BE27: 53 | BF27: 51 | BG27: 66 | BH27: 85 | BI27: 60 | BJ27: 67 | BK27: 64 | BL27: 61 | BM27: 76 | BN27: 55 | BO27: 55 | BP27: 44 | BQ27: 58 | BR27: 85 | BS27: 65 | BT27: 52 | BU27: 42 | BV27: 45 | BW27: 65 | BX27: 45 | BY27: 72 | BZ27: 52 | CB27: 51 | CC27: 49 | CD27: 49 | CE27: 70 | CF27: 76 | CG27: 73 | CH27: 69 | CI27: 58 | CJ27: 48 | CK27: 65 | CL27: 70 | CM27: 72 | CN27: 62 | CO27: 45 | CP27: 76 | CQ27: 76 | CR27: 97 | CS27: 91 | CT27: 31 | CU27: 29 | CV27: 50 | CW27: 59 | CX27: 49 | CY27: 46 | CZ27: 58 | DA27: 59 | DB27: 54 | DC27: 65 | DD27: 65 | DE27: 44 | DF27: 78 | DG27: 55 | DH27: 42 | DI27: 60 | DJ27: 64 | DK27: 54 | DM27: 69 | DN27: 49 | DO27: 47 | DP27: 68 | DQ27: 48 | DR27: 85 | DS27: 77 | DT27: 86 | DU27: 61 | DV27: 68 | DW27: 81 | DX27: 50 | DY27: 36 | DZ27: 34 | EA27: 38 | EB27: 43 | EC27: 53 | ED27: 64 | EE27: 80 | EF27: 44 | EG27: 38 | EH27: 42 | EI27: 51 | EJ27: 42 | EK27: 51 | EL27: 56 | EM27: 72 | EN27: 51 | EO27: 54 | EP27: 46 | EQ27: 46 | ER27: 46 | ES27: 40 | ET27: 64
B28: Weather condition | C28: list
B29: Pump and others | C29: list, if a problem
B31: FIELD AND WORK - FP plot / মাঠ ও কাজ
B32: Field condition | C32: list
B33: Condition | C33: list | BD33: Good | BE33: Good | BF33: Good | BG33: Good | BH33: Good | BI33: Good | BJ33: Good | BK33: Good | BL33: Good | BM33: Good | BN33: Good | BO33: Good | BP33: Good | BQ33: Good | BR33: Good | BS33: Good | BT33: Good | BU33: Good | BV33: Good | BW33: Good | BX33: Good | BY33: Good | BZ33: Good | CB33: Good | CC33: Good | CD33: Good | CE33: Good | CF33: Good | CG33: Good | CH33: Good | CI33: Good | CJ33: Good | CK33: Good | CL33: Good | CM33: Good | CN33: Good | CO33: Good | CP33: Good | CQ33: Good | CR33: Good | CS33: Good | CT33: Good | CU33: Good | CV33: Good | CW33: Good | CX33: Good | CY33: Good | CZ33: Good | DA33: Good | DB33: Good | DC33: Good | DD33: Good | DE33: Good | DF33: Good | DG33: Good | DH33: Good | DI33: Good | DJ33: Good | DK33: Good | DM33: Good | DN33: Good | DO33: Good | DP33: Good | DQ33: Good | DR33: Good | DS33: Good | DT33: Good | DU33: Good | DV33: Good | DW33: Good | DX33: Good | DY33: Good | DZ33: Good | EA33: Good | EB33: Good | EC33: Good | ED33: Good | EE33: Good | EF33: Good | EG33: Good | EH33: Good | EI33: Good | EJ33: Good | EK33: Good | EL33: Good | EM33: Good | EN33: Good | EO33: Good | EP33: Good | EQ33: Good | ER33: Good | ES33: Good | ET33: Good
B34: Farmer (land owner) work time (min) | C34: number | BE34: 20 | BG34: 20 | BK34: 20 | BP34: 20 | BW34: 20 | CD34: 20 | CH34: 20 | CW34: 20 | CZ34: 20 | DC34: 20 | DI34: 20 | DJ34: 20 | DM34: 20 | DO34: 20 | DR34: 20 | DT34: 20 | DW34: 20 | EA34: 20 | EH34: 20 | EJ34: 20 | EP34: 20
B35: Farmer work contents | C35: list | BE35: Irrigation | BG35: Irrigation | BK35: Irrigation | BP35: Irrigation | BW35: Irrigation | CD35: Irrigation | CH35: Irrigation | CW35: Irrigation | CZ35: Irrigation | DC35: Irrigation | DI35: Irrigation | DJ35: Irrigation | DM35: Irrigation | DO35: Irrigation | DR35: Irrigation | DT35: Irrigation | DW35: Irrigation | EA35: Irrigation | EH35: Irrigation | EJ35: Irrigation | EP35: Irrigation
B36: Labour cost (BDT) | C36: number
B37: Labour work contents | C37: list
B39: FIELD AND WORK - 3F4D+MD plot / মাঠ ও কাজ
B40: Field condition | C40: list
B41: Condition | C41: list | BD41: Good | BE41: Good | BF41: Good | BG41: Good | BH41: Good | BI41: Good | BJ41: Good | BK41: Good | BL41: Good | BM41: Good | BN41: Good | BO41: Good | BP41: Good | BQ41: Good | BR41: Good | BS41: Good | BT41: Good | BU41: Good | BV41: Good | BW41: Good | BX41: Good | BY41: Good | BZ41: Good | CB41: Good | CC41: Good | CD41: Good | CE41: Good | CF41: Good | CG41: Good | CH41: Good | CI41: Good | CJ41: Good | CK41: Good | CL41: Good | CM41: Good | CN41: Good | CO41: Good | CP41: Good | CQ41: Good | CR41: Good | CS41: Good | CT41: Good | CU41: Good | CV41: Good | CW41: Good | CX41: Good | CY41: Good | CZ41: Good | DA41: Good | DB41: Good | DC41: Good | DD41: Good | DE41: Good | DF41: Good | DG41: Good | DH41: Good | DI41: Good | DJ41: Good | DK41: Good | DM41: Good | DN41: Good | DO41: Good | DP41: Good | DQ41: Good | DR41: Good | DS41: Good | DT41: Good | DU41: Good | DV41: Good | DW41: Good | DX41: Good | DY41: Good | DZ41: Good | EA41: Good | EB41: Good | EC41: Good | ED41: Good | EE41: Good | EF41: Good | EG41: Good | EH41: Good | EI41: Good | EJ41: Good | EK41: Good | EL41: Good | EM41: Good | EN41: Good | EO41: Good | EP41: Good | EQ41: Good | ER41: Good | ES41: Good | ET41: Good
B42: Farmer (land owner) work time (min) | C42: number | BE42: 20 | BG42: 20 | BK42: 20 | BP42: 20 | BW42: 20 | CD42: 20 | CH42: 20 | CW42: 20 | CZ42: 20 | DC42: 20 | DG42: 20 | DN42: 20 | DU42: 20 | EB42: 20 | EJ42: 20
B43: Farmer work contents | C43: list | BE43: Irrigation | BG43: Irrigation | BK43: Irrigation | BP43: Irrigation | BW43: Irrigation | CD43: Irrigation | CH43: Irrigation | CW43: Irrigation | CZ43: Irrigation | DC43: Irrigation | DG43: Irrigation | DN43: Irrigation | DU43: Irrigation | EB43: Irrigation | EJ43: Irrigation
B44: Labour cost (BDT) | C44: number
B45: Labour work contents | C45: list
...

Sheet Calendar
A1: Calendar / ক্যালেন্ডার
A2: =IF(SiteName="","",SiteName&IF(Place="",""," - "&Place)) -> Demo Site-03 - Pirganj, Rangpur | F2: =IF(Variety="","","Variety: "&Variety) -> Variety: BRRI dhan58
B4: 3F4D+MD activities | C4: Planned | D4: Actual | G4: FP activities | H4: Planned | I4: Actual
A5: 01. | B5: =Schedule_Farmer!A5&IF(Schedule_Farmer!E5<>Schedule_Farmer!D5," (to "&TEXT(Schedule_Farmer!E5,"dd mmm")&")","") -> Seed wetting | C5: =IF(Schedule_Farmer!D5="","",Schedule_Farmer!D5) -> 45986 | D5: =IF(Schedule_Farmer!F5="","",Schedule_Farmer!F5) -> 45986 | F5: 01. | G5: =Schedule_Farmer!A28&IF(Schedule_Farmer!E28<>Schedule_Farmer!D28," (to "&TEXT(Schedule_Farmer!E28,"dd mmm")&")","") -> Seed wetting | H5: =IF(Schedule_Farmer!D28="","",Schedule_Farmer!D28) -> 45986 | I5: =IF(Schedule_Farmer!F28="","",Schedule_Farmer!F28) -> 45986
A6: 02. | B6: =Schedule_Farmer!A6&IF(Schedule_Farmer!E6<>Schedule_Farmer!D6," (to "&TEXT(Schedule_Farmer!E6,"dd mmm")&")","") -> Sowing | C6: =IF(Schedule_Farmer!D6="","",Schedule_Farmer!D6) -> 45989 | D6: =IF(Schedule_Farmer!F6="","",Schedule_Farmer!F6) -> 45989 | F6: 02. | G6: =Schedule_Farmer!A29&IF(Schedule_Farmer!E29<>Schedule_Farmer!D29," (to "&TEXT(Schedule_Farmer!E29,"dd mmm")&")","") -> Sowing | H6: =IF(Schedule_Farmer!D29="","",Schedule_Farmer!D29) -> 45989 | I6: =IF(Schedule_Farmer!F29="","",Schedule_Farmer!F29) -> 45989
A7: 03. | B7: =Schedule_Farmer!A7&IF(Schedule_Farmer!E7<>Schedule_Farmer!D7," (to "&TEXT(Schedule_Farmer!E7,"dd mmm")&")","") -> Plowing | C7: =IF(Schedule_Farmer!D7="","",Schedule_Farmer!D7) -> 45995 | D7: =IF(Schedule_Farmer!F7="","",Schedule_Farmer!F7) | F7: 03. | G7: =Schedule_Farmer!A30&IF(Schedule_Farmer!E30<>Schedule_Farmer!D30," (to "&TEXT(Schedule_Farmer!E30,"dd mmm")&")","") -> Plowing | H7: =IF(Schedule_Farmer!D30="","",Schedule_Farmer!D30) -> 45995 | I7: =IF(Schedule_Farmer!F30="","",Schedule_Farmer!F30)
A8: 04. | B8: =Schedule_Farmer!A8&IF(Schedule_Farmer!E8<>Schedule_Farmer!D8," (to "&TEXT(Schedule_Farmer!E8,"dd mmm")&")","") -> Puddling | C8: =IF(Schedule_Farmer!D8="","",Schedule_Farmer!D8) -> 46025 | D8: =IF(Schedule_Farmer!F8="","",Schedule_Farmer!F8) | F8: 04. | G8: =Schedule_Farmer!A31&IF(Schedule_Farmer!E31<>Schedule_Farmer!D31," (to "&TEXT(Schedule_Farmer!E31,"dd mmm")&")","") -> Puddling | H8: =IF(Schedule_Farmer!D31="","",Schedule_Farmer!D31) -> 46025 | I8: =IF(Schedule_Farmer!F31="","",Schedule_Farmer!F31)
A9: 05. | B9: =Schedule_Farmer!A9&IF(Schedule_Farmer!E9<>Schedule_Farmer!D9," (to "&TEXT(Schedule_Farmer!E9,"dd mmm")&")","") -> Transplanting | C9: =IF(Schedule_Farmer!D9="","",Schedule_Farmer!D9) -> 46038 | D9: =IF(Schedule_Farmer!F9="","",Schedule_Farmer!F9) -> 46038 | F9: 05. | G9: =Schedule_Farmer!A32&IF(Schedule_Farmer!E32<>Schedule_Farmer!D32," (to "&TEXT(Schedule_Farmer!E32,"dd mmm")&")","") -> Transplanting | H9: =IF(Schedule_Farmer!D32="","",Schedule_Farmer!D32) -> 46038 | I9: =IF(Schedule_Farmer!F32="","",Schedule_Farmer!F32) -> 46038
A10: 06. | B10: =Schedule_Farmer!A10&IF(Schedule_Farmer!E10<>Schedule_Farmer!D10," (to "&TEXT(Schedule_Farmer!E10,"dd mmm")&")","") -> Last irrigation for Pitan | C10: =IF(Schedule_Farmer!D10="","",Schedule_Farmer!D10) -> 46064 | D10: =IF(Schedule_Farmer!F10="","",Schedule_Farmer!F10) | F10: 06. | G10: =Schedule_Farmer!A33&IF(Schedule_Farmer!E33<>Schedule_Farmer!D33," (to "&TEXT(Schedule_Farmer!E33,"dd mmm")&")","") -> Last irrigation for Pitan | H10: =IF(Schedule_Farmer!D33="","",Schedule_Farmer!D33) -> 46064 | I10: =IF(Schedule_Farmer!F33="","",Schedule_Farmer!F33)
A11: 07. | B11: =Schedule_Farmer!A11&IF(Schedule_Farmer!E11<>Schedule_Farmer!D11," (to "&TEXT(Schedule_Farmer!E11,"dd mmm")&")","") -> Pitan (conventional mid-season drainage) (to 18 Feb) | C11: =IF(Schedule_Farmer!D11="","",Schedule_Farmer!D11) -> 46068 | D11: =IF(Schedule_Farmer!F11="","",Schedule_Farmer!F11) | F11: 07. | G11: =Schedule_Farmer!A34&IF(Schedule_Farmer!E34<>Schedule_Farmer!D34," (to "&TEXT(Schedule_Farmer!E34,"dd mmm")&")","") -> Pitan (FP) (to 23 Feb) | H11: =IF(Schedule_Farmer!D34="","",Schedule_Farmer!D34) -> 46068 | I11: =IF(Schedule_Farmer!F34="","",Schedule_Farmer!F34)
A12: 08. | B12: =Schedule_Farmer!A12&IF(Schedule_Farmer!E12<>Schedule_Farmer!D12," (to "&TEXT(Schedule_Farmer!E12,"dd mmm")&")","") -> Last irrigation for starting MD | C12: =IF(Schedule_Farmer!D12="","",Schedule_Farmer!D12) -> 46065 | D12: =IF(Schedule_Farmer!F12="","",Schedule_Farmer!F12) | F12: 08. | G12: =Schedule_Farmer!A35&IF(Schedule_Farmer!E35<>Schedule_Farmer!D35," (to "&TEXT(Schedule_Farmer!E35,"dd mmm")&")","") -> Flooding after Pitan | H12: =IF(Schedule_Farmer!D35="","",Schedule_Farmer!D35) -> 46076 | I12: =IF(Schedule_Farmer!F35="","",Schedule_Farmer!F35)
A13: 09. | B13: =Schedule_Farmer!A13&IF(Schedule_Farmer!E13<>Schedule_Farmer!D13," (to "&TEXT(Schedule_Farmer!E13,"dd mmm")&")","") -> Mid-season drainage (MD; start = surface water disappears) (to 24 Feb) | C13: =IF(Schedule_Farmer!D13="","",Schedule_Farmer!D13) -> 46069 | D13: =IF(Schedule_Farmer!F13="","",Schedule_Farmer!F13) | F13: 09. | G13: =Schedule_Farmer!A36&IF(Schedule_Farmer!E36<>Schedule_Farmer!D36," (to "&TEXT(Schedule_Farmer!E36,"dd mmm")&")","") -> Heading | H13: =IF(Schedule_Farmer!D36="","",Schedule_Farmer!D36) -> 46114 | I13: =IF(Schedule_Farmer!F36="","",Schedule_Farmer!F36)
A14: 10. | B14: =Schedule_Farmer!A14&IF(Schedule_Farmer!E14<>Schedule_Farmer!D14," (to "&TEXT(Schedule_Farmer!E14,"dd mmm")&")","") -> Panicle checking (PI check) | C14: =IF(Schedule_Farmer!D14="","",Schedule_Farmer!D14) -> 46075 | D14: =IF(Schedule_Farmer!F14="","",Schedule_Farmer!F14) | F14: 10. | G14: =Schedule_Farmer!A37&IF(Schedule_Farmer!E37<>Schedule_Farmer!D37," (to "&TEXT(Schedule_Farmer!E37,"dd mmm")&")","") -> Last irrigation | H14: =IF(Schedule_Farmer!D37="","",Schedule_Farmer!D37) -> 46127 | I14: =IF(Schedule_Farmer!F37="","",Schedule_Farmer!F37)
A15: 11. | B15: =Schedule_Farmer!A15&IF(Schedule_Farmer!E15<>Schedule_Farmer!D15," (to "&TEXT(Schedule_Farmer!E15,"dd mmm")&")","") -> Flooding (panicle initiation) (to 12 Mar) | C15: =IF(Schedule_Farmer!D15="","",Schedule_Farmer!D15) -> 46089 | D15: =IF(Schedule_Farmer!F15="","",Schedule_Farmer!F15) | F15: 11. | G15: =Schedule_Farmer!A38&IF(Schedule_Farmer!E38<>Schedule_Farmer!D38," (to "&TEXT(Schedule_Farmer!E38,"dd mmm")&")","") -> Harvest | H15: =IF(Schedule_Farmer!D38="","",Schedule_Farmer!D38) -> 46142 | I15: =IF(Schedule_Farmer!F38="","",Schedule_Farmer!F38)
A16: 12. | B16: =Schedule_Farmer!A16&IF(Schedule_Farmer!E16<>Schedule_Farmer!D16," (to "&TEXT(Schedule_Farmer!E16,"dd mmm")&")","") -> 3F4D-1 (to 19 Mar) | C16: =IF(Schedule_Farmer!D16="","",Schedule_Farmer!D16) -> 46093 | D16: =IF(Schedule_Farmer!F16="","",Schedule_Farmer!F16)
A17: 13. | B17: =Schedule_Farmer!A17&IF(Schedule_Farmer!E17<>Schedule_Farmer!D17," (to "&TEXT(Schedule_Farmer!E17,"dd mmm")&")","") -> 3F4D-2 (to 26 Mar) | C17: =IF(Schedule_Farmer!D17="","",Schedule_Farmer!D17) -> 46100 | D17: =IF(Schedule_Farmer!F17="","",Schedule_Farmer!F17)
A18: 14. | B18: =Schedule_Farmer!A18&IF(Schedule_Farmer!E18<>Schedule_Farmer!D18," (to "&TEXT(Schedule_Farmer!E18,"dd mmm")&")","") -> 3F4D-3 (to 02 Apr) | C18: =IF(Schedule_Farmer!D18="","",Schedule_Farmer!D18) -> 46107 | D18: =IF(Schedule_Farmer!F18="","",Schedule_Farmer!F18)
A19: 15. | B19: =Schedule_Farmer!A19&IF(Schedule_Farmer!E19<>Schedule_Farmer!D19," (to "&TEXT(Schedule_Farmer!E19,"dd mmm")&")","") -> Heading | C19: =IF(Schedule_Farmer!D19="","",Schedule_Farmer!D19) -> 46114 | D19: =IF(Schedule_Farmer!F19="","",Schedule_Farmer!F19)
A20: 16. | B20: =Schedule_Farmer!A20&IF(Schedule_Farmer!E20<>Schedule_Farmer!D20," (to "&TEXT(Schedule_Farmer!E20,"dd mmm")&")","") -> 3F4D-4 (to 09 Apr) | C20: =IF(Schedule_Farmer!D20="","",Schedule_Farmer!D20) -> 46114 | D20: =IF(Schedule_Farmer!F20="","",Schedule_Farmer!F20)
A21: 17. | B21: =Schedule_Farmer!A21&IF(Schedule_Farmer!E21<>Schedule_Farmer!D21," (to "&TEXT(Schedule_Farmer!E21,"dd mmm")&")","") -> 3F4D-5 (to 16 Apr) | C21: =IF(Schedule_Farmer!D21="","",Schedule_Farmer!D21) -> 46121 | D21: =IF(Schedule_Farmer!F21="","",Schedule_Farmer!F21) -> 46122
A22: 18. | B22: =Schedule_Farmer!A22&IF(Schedule_Farmer!E22<>Schedule_Farmer!D22," (to "&TEXT(Schedule_Farmer!E22,"dd mmm")&")","") -> 3F4D-6 (to 23 Apr) | C22: =IF(Schedule_Farmer!D22="","",Schedule_Farmer!D22) -> 46128 | D22: =IF(Schedule_Farmer!F22="","",Schedule_Farmer!F22) -> 46129
A23: 19. | B23: =Schedule_Farmer!A23&IF(Schedule_Farmer!E23<>Schedule_Farmer!D23," (to "&TEXT(Schedule_Farmer!E23,"dd mmm")&")","") -> 3F4D end | C23: =IF(Schedule_Farmer!D23="","",Schedule_Farmer!D23) -> 46135 | D23: =IF(Schedule_Farmer!F23="","",Schedule_Farmer!F23) -> 46136
A24: 20. | B24: =Schedule_Farmer!A24&IF(Schedule_Farmer!E24<>Schedule_Farmer!D24," (to "&TEXT(Schedule_Farmer!E24,"dd mmm")&")","") -> Last irrigation | C24: =IF(Schedule_Farmer!D24="","",Schedule_Farmer!D24) -> 46136 | D24: =IF(Schedule_Farmer!F24="","",Schedule_Farmer!F24)
A25: 21. | B25: =Schedule_Farmer!A25&IF(Schedule_Farmer!E25<>Schedule_Farmer!D25," (to "&TEXT(Schedule_Farmer!E25,"dd mmm")&")","") -> Harvest | C25: =IF(Schedule_Farmer!D25="","",Schedule_Farmer!D25) -> 46142 | D25: =IF(Schedule_Farmer!F25="","",Schedule_Farmer!F25)
A27: Pitan and the last irrigation are optional and may be carried out or omitted. Actual dates: 2_Daily_input, rows "SCHEDULE WORK DONE".
B29: Tiller (stem) number measurement | C29: Date
B30: Day 50 after sowing | C30: =IF(ISNUMBER(SowDate),SowDate+50,"") -> 46039
B31: Day 60 after sowing | C31: =IF(ISNUMBER(SowDate),SowDate+60,"") -> 46049
B32: Day 70 after sowing | C32: =IF(ISNUMBER(SowDate),SowDate+70,"") -> 46059
B33: Day 80 after sowing | C33: =IF(ISNUMBER(SowDate),SowDate+80,"") -> 46069
B34: Day 90 after sowing | C34: =IF(ISNUMBER(SowDate),SowDate+90,"") -> 46079
B36: Water sampling: once a week

Sheet Today
A1: =IF(SiteName="","3F4D Water Monitor",SiteName&IF(Place="",""," - "&Place)) -> Demo Site-03 - Pirganj, Rangpur
A3: Today / আজ | B3: =TODAY() -> 46314
A4: Days after transplanting | B4: =IF(ISNUMBER(TransDate),TODAY()-TransDate,"") -> 276
A5: Today's water level / আজকের পানির স্তর | B5: =IF(ISNA(MATCH(TODAY(),Data_Farmer!$D$1:$FQ$1,0)),"(today is not in 2_Daily_input)",IF(AND(ISNUMBER(INDEX(Data_Farmer!$D$12:$FQ$12,MATCH(TODAY(),Data_Farmer!$D$1:$FQ$1,0))),ISNUMBER(INDEX(Data_Farmer!$D$37:$FQ$37,MATCH(TODAY(),Data_Farmer!$D$1:$FQ$1,0)))),"Entered","NOT YET ENTERED")) -> (today is not in 2_Daily_input)
A6: Last entry | B6: =IF(_xlfn.MAXIFS(Data_Farmer!$D$1:$FQ$1,Data_Farmer!$D$33:$FQ$33,1)=0,"",_xlfn.MAXIFS(Data_Farmer!$D$1:$FQ$1,Data_Farmer!$D$33:$FQ$33,1)) -> 46132
A7: Days without entry | B7: =IF(B6="","",MAX(0,TODAY()-B6-1)) -> 181
A8: Stage today | B8: =IFERROR(INDEX(Data_Farmer!$D$6:$FQ$6,MATCH(TODAY(),Data_Farmer!$D$1:$FQ$1,0)),"")
B10: FP | C10: 3F4D+MD
A11: Latest water level - date | B11: =IF(_xlfn.MAXIFS(Data_Farmer!$D$1:$FQ$1,Data_Farmer!$D$33:$FQ$33,1)=0,"",_xlfn.MAXIFS(Data_Farmer!$D$1:$FQ$1,Data_Farmer!$D$33:$FQ$33,1)) -> 46132 | C11: =IF(_xlfn.MAXIFS(Data_Farmer!$D$1:$FQ$1,Data_Farmer!$D$58:$FQ$58,1)=0,"",_xlfn.MAXIFS(Data_Farmer!$D$1:$FQ$1,Data_Farmer!$D$58:$FQ$58,1)) -> 46132
A12: Water level (cm, after irrigation if irrigated) | B12: =IF(B11="","",INDEX(Data_Farmer!$D$32:$FQ$32,MATCH(B11,Data_Farmer!$D$1:$FQ$1,0))) -> -15 | C12: =IF(C11="","",INDEX(Data_Farmer!$D$57:$FQ$57,MATCH(C11,Data_Farmer!$D$1:$FQ$1,0))) -> -15
A13: State | B13: =IF(B12="","",IF(B12>0,"water above the soil surface",IF(B12<0,"water below the soil surface","at the soil surface"))) -> water below the soil surface | C13: =IF(C12="","",IF(C12>0,"water above the soil surface",IF(C12<0,"water below the soil surface","at the soil surface"))) -> water below the soil surface
A14: Total irrigation (mm) | B14: =ROUND(SUM(Data_Farmer!$D$21:$FQ$21),0) -> 377 | C14: =ROUND(SUM(Data_Farmer!$D$46:$FQ$46),0) -> 271
A15: Number of irrigations | B15: =COUNT(Data_Farmer!$D$21:$FQ$21) -> 21 | C15: =COUNT(Data_Farmer!$D$46:$FQ$46) -> 15
A16: Water saving by 3F4D+MD | B16: =IF(B14=0,"",B14-C14&" mm") -> 106 mm | C16: =IF(B14=0,"",ROUND(100*(B14-C14)/B14,0)&" %") -> 28 %
A17: Farmer working time (min) | B17: =SUM(Data_Farmer!$D$26:$FQ$26) -> 420 | C17: =SUM(Data_Farmer!$D$51:$FQ$51) -> 300
A18: Labour (BDT) | B18: =SUM(Data_Farmer!$D$28:$FQ$28) -> 0 | C18: =SUM(Data_Farmer!$D$53:$FQ$53) -> 0
A19: N applied (kg/10a) | B19: =Other_info!$B$18 -> 20.2 | C19: =Other_info!$B$19 -> 20.2
A20: P applied (kg/10a) | B20: =Other_info!$C$18 -> 2.3 | C20: =Other_info!$C$19 -> 2.3
B22: Next events (schedule) | C22: Date
A23: Next 1 | B23: =IFERROR(INDEX(Schedule_Farmer!$A$5:$A$38,MATCH(SMALL(Schedule_Farmer!$L$5:$L$38,1),Schedule_Farmer!$L$5:$L$38,0))&" ("&INDEX(Schedule_Farmer!$C$5:$C$38,MATCH(SMALL(Schedule_Farmer!$L$5:$L$38,1),Schedule_Farmer!$L$5:$L$38,0))&")","") | C23: =IFERROR(INT(SMALL(Schedule_Farmer!$L$5:$L$38,1)),"") | D23: =IF(C23="","",IF(C23-TODAY()=0,"today","in "&(C23-TODAY())&" days"))
A24: Next 2 | B24: =IFERROR(INDEX(Schedule_Farmer!$A$5:$A$38,MATCH(SMALL(Schedule_Farmer!$L$5:$L$38,2),Schedule_Farmer!$L$5:$L$38,0))&" ("&INDEX(Schedule_Farmer!$C$5:$C$38,MATCH(SMALL(Schedule_Farmer!$L$5:$L$38,2),Schedule_Farmer!$L$5:$L$38,0))&")","") | C24: =IFERROR(INT(SMALL(Schedule_Farmer!$L$5:$L$38,2)),"") | D24: =IF(C24="","",IF(C24-TODAY()=0,"today","in "&(C24-TODAY())&" days"))
A25: Next 3 | B25: =IFERROR(INDEX(Schedule_Farmer!$A$5:$A$38,MATCH(SMALL(Schedule_Farmer!$L$5:$L$38,3),Schedule_Farmer!$L$5:$L$38,0))&" ("&INDEX(Schedule_Farmer!$C$5:$C$38,MATCH(SMALL(Schedule_Farmer!$L$5:$L$38,3),Schedule_Farmer!$L$5:$L$38,0))&")","") | C25: =IFERROR(INT(SMALL(Schedule_Farmer!$L$5:$L$38,3)),"") | D25: =IF(C25="","",IF(C25-TODAY()=0,"today","in "&(C25-TODAY())&" days"))
A26: Next 4 | B26: =IFERROR(INDEX(Schedule_Farmer!$A$5:$A$38,MATCH(SMALL(Schedule_Farmer!$L$5:$L$38,4),Schedule_Farmer!$L$5:$L$38,0))&" ("&INDEX(Schedule_Farmer!$C$5:$C$38,MATCH(SMALL(Schedule_Farmer!$L$5:$L$38,4),Schedule_Farmer!$L$5:$L$38,0))&")","") | C26: =IFERROR(INT(SMALL(Schedule_Farmer!$L$5:$L$38,4)),"") | D26: =IF(C26="","",IF(C26-TODAY()=0,"today","in "&(C26-TODAY())&" days"))
A28: Actual date not entered (overdue events) | B28: =COUNTIF(Schedule_Farmer!$H$5:$H$38,"OVERDUE") -> 23

Sheet Graphs
A1: Graphs / গ্রাফ (MD, Pitan and 3F4D periods are drawn as lines at the top of the water-level graph)

Sheet Schedule_Farmer
A1: Schedule / সময়সূচি (automatic - do not enter here. Actual dates come from 2_Daily_input, rows "SCHEDULE WORK DONE")
M2: =IF(ISNUMBER(SowDate),SowDate-3+0,"") -> 45986 | N2: =IF(ISNUMBER(SowDate),SowDate-3+1,"") -> 45987 | O2: =IF(ISNUMBER(SowDate),SowDate-3+2,"") -> 45988 | P2: =IF(ISNUMBER(SowDate),SowDate-3+3,"") -> 45989 | Q2: =IF(ISNUMBER(SowDate),SowDate-3+4,"") -> 45990 | R2: =IF(ISNUMBER(SowDate),SowDate-3+5,"") -> 45991 | S2: =IF(ISNUMBER(SowDate),SowDate-3+6,"") -> 45992 | T2: =IF(ISNUMBER(SowDate),SowDate-3+7,"") -> 45993 | U2: =IF(ISNUMBER(SowDate),SowDate-3+8,"") -> 45994 | V2: =IF(ISNUMBER(SowDate),SowDate-3+9,"") -> 45995 | W2: =IF(ISNUMBER(SowDate),SowDate-3+10,"") -> 45996 | X2: =IF(ISNUMBER(SowDate),SowDate-3+11,"") -> 45997 | Y2: =IF(ISNUMBER(SowDate),SowDate-3+12,"") -> 45998 | Z2: =IF(ISNUMBER(SowDate),SowDate-3+13,"") -> 45999 | AA2: =IF(ISNUMBER(SowDate),SowDate-3+14,"") -> 46000 | AB2: =IF(ISNUMBER(SowDate),SowDate-3+15,"") -> 46001 | AC2: =IF(ISNUMBER(SowDate),SowDate-3+16,"") -> 46002 | AD2: =IF(ISNUMBER(SowDate),SowDate-3+17,"") -> 46003 | AE2: =IF(ISNUMBER(SowDate),SowDate-3+18,"") -> 46004 | AF2: =IF(ISNUMBER(SowDate),SowDate-3+19,"") -> 46005 | AG2: =IF(ISNUMBER(SowDate),SowDate-3+20,"") -> 46006 | AH2: =IF(ISNUMBER(SowDate),SowDate-3+21,"") -> 46007 | AI2: =IF(ISNUMBER(SowDate),SowDate-3+22,"") -> 46008 | AJ2: =IF(ISNUMBER(SowDate),SowDate-3+23,"") -> 46009 | AK2: =IF(ISNUMBER(SowDate),SowDate-3+24,"") -> 46010 | AL2: =IF(ISNUMBER(SowDate),SowDate-3+25,"") -> 46011 | AM2: =IF(ISNUMBER(SowDate),SowDate-3+26,"") -> 46012 | AN2: =IF(ISNUMBER(SowDate),SowDate-3+27,"") -> 46013 | AO2: =IF(ISNUMBER(SowDate),SowDate-3+28,"") -> 46014 | AP2: =IF(ISNUMBER(SowDate),SowDate-3+29,"") -> 46015 | AQ2: =IF(ISNUMBER(SowDate),SowDate-3+30,"") -> 46016 | AR2: =IF(ISNUMBER(SowDate),SowDate-3+31,"") -> 46017 | AS2: =IF(ISNUMBER(SowDate),SowDate-3+32,"") -> 46018 | AT2: =IF(ISNUMBER(SowDate),SowDate-3+33,"") -> 46019 | AU2: =IF(ISNUMBER(SowDate),SowDate-3+34,"") -> 46020 | AV2: =IF(ISNUMBER(SowDate),SowDate-3+35,"") -> 46021 | AW2: =IF(ISNUMBER(SowDate),SowDate-3+36,"") -> 46022 | AX2: =IF(ISNUMBER(SowDate),SowDate-3+37,"") -> 46023 | AY2: =IF(ISNUMBER(SowDate),SowDate-3+38,"") -> 46024 | AZ2: =IF(ISNUMBER(SowDate),SowDate-3+39,"") -> 46025 | BA2: =IF(ISNUMBER(SowDate),SowDate-3+40,"") -> 46026 | BB2: =IF(ISNUMBER(SowDate),SowDate-3+41,"") -> 46027 | BC2: =IF(ISNUMBER(SowDate),SowDate-3+42,"") -> 46028 | BD2: =IF(ISNUMBER(SowDate),SowDate-3+43,"") -> 46029 | BE2: =IF(ISNUMBER(SowDate),SowDate-3+44,"") -> 46030 | BF2: =IF(ISNUMBER(SowDate),SowDate-3+45,"") -> 46031 | BG2: =IF(ISNUMBER(SowDate),SowDate-3+46,"") -> 46032 | BH2: =IF(ISNUMBER(SowDate),SowDate-3+47,"") -> 46033 | BI2: =IF(ISNUMBER(SowDate),SowDate-3+48,"") -> 46034 | BJ2: =IF(ISNUMBER(SowDate),SowDate-3+49,"") -> 46035 | BK2: =IF(ISNUMBER(SowDate),SowDate-3+50,"") -> 46036 | BL2: =IF(ISNUMBER(SowDate),SowDate-3+51,"") -> 46037 | BM2: =IF(ISNUMBER(SowDate),SowDate-3+52,"") -> 46038 | BN2: =IF(ISNUMBER(SowDate),SowDate-3+53,"") -> 46039 | BO2: =IF(ISNUMBER(SowDate),SowDate-3+54,"") -> 46040 | BP2: =IF(ISNUMBER(SowDate),SowDate-3+55,"") -> 46041 | BQ2: =IF(ISNUMBER(SowDate),SowDate-3+56,"") -> 46042 | BR2: =IF(ISNUMBER(SowDate),SowDate-3+57,"") -> 46043 | BS2: =IF(ISNUMBER(SowDate),SowDate-3+58,"") -> 46044 | BT2: =IF(ISNUMBER(SowDate),SowDate-3+59,"") -> 46045 | BU2: =IF(ISNUMBER(SowDate),SowDate-3+60,"") -> 46046 | BV2: =IF(ISNUMBER(SowDate),SowDate-3+61,"") -> 46047 | BW2: =IF(ISNUMBER(SowDate),SowDate-3+62,"") -> 46048 | BX2: =IF(ISNUMBER(SowDate),SowDate-3+63,"") -> 46049 | BY2: =IF(ISNUMBER(SowDate),SowDate-3+64,"") -> 46050 | BZ2: =IF(ISNUMBER(SowDate),SowDate-3+65,"") -> 46051 | CA2: =IF(ISNUMBER(SowDate),SowDate-3+66,"") -> 46052 | CB2: =IF(ISNUMBER(SowDate),SowDate-3+67,"") -> 46053 | CC2: =IF(ISNUMBER(SowDate),SowDate-3+68,"") -> 46054 | CD2: =IF(ISNUMBER(SowDate),SowDate-3+69,"") -> 46055 | CE2: =IF(ISNUMBER(SowDate),SowDate-3+70,"") -> 46056 | CF2: =IF(ISNUMBER(SowDate),SowDate-3+71,"") -> 46057 | CG2: =IF(ISNUMBER(SowDate),SowDate-3+72,"") -> 46058 | CH2: =IF(ISNUMBER(SowDate),SowDate-3+73,"") -> 46059 | CI2: =IF(ISNUMBER(SowDate),SowDate-3+74,"") -> 46060 | CJ2: =IF(ISNUMBER(SowDate),SowDate-3+75,"") -> 46061 | CK2: =IF(ISNUMBER(SowDate),SowDate-3+76,"") -> 46062 | CL2: =IF(ISNUMBER(SowDate),SowDate-3+77,"") -> 46063 | CM2: =IF(ISNUMBER(SowDate),SowDate-3+78,"") -> 46064 | CN2: =IF(ISNUMBER(SowDate),SowDate-3+79,"") -> 46065 | CO2: =IF(ISNUMBER(SowDate),SowDate-3+80,"") -> 46066 | CP2: =IF(ISNUMBER(SowDate),SowDate-3+81,"") -> 46067 | CQ2: =IF(ISNUMBER(SowDate),SowDate-3+82,"") -> 46068 | CR2: =IF(ISNUMBER(SowDate),SowDate-3+83,"") -> 46069 | CS2: =IF(ISNUMBER(SowDate),SowDate-3+84,"") -> 46070 | CT2: =IF(ISNUMBER(SowDate),SowDate-3+85,"") -> 46071 | CU2: =IF(ISNUMBER(SowDate),SowDate-3+86,"") -> 46072 | CV2: =IF(ISNUMBER(SowDate),SowDate-3+87,"") -> 46073 | CW2: =IF(ISNUMBER(SowDate),SowDate-3+88,"") -> 46074 | CX2: =IF(ISNUMBER(SowDate),SowDate-3+89,"") -> 46075 | CY2: =IF(ISNUMBER(SowDate),SowDate-3+90,"") -> 46076 | CZ2: =IF(ISNUMBER(SowDate),SowDate-3+91,"") -> 46077 | DA2: =IF(ISNUMBER(SowDate),SowDate-3+92,"") -> 46078 | DB2: =IF(ISNUMBER(SowDate),SowDate-3+93,"") -> 46079 | DC2: =IF(ISNUMBER(SowDate),SowDate-3+94,"") -> 46080 | DD2: =IF(ISNUMBER(SowDate),SowDate-3+95,"") -> 46081 | DE2: =IF(ISNUMBER(SowDate),SowDate-3+96,"") -> 46082 | DF2: =IF(ISNUMBER(SowDate),SowDate-3+97,"") -> 46083 | DG2: =IF(ISNUMBER(SowDate),SowDate-3+98,"") -> 46084 | DH2: =IF(ISNUMBER(SowDate),SowDate-3+99,"") -> 46085 | DI2: =IF(ISNUMBER(SowDate),SowDate-3+100,"") -> 46086 | DJ2: =IF(ISNUMBER(SowDate),SowDate-3+101,"") -> 46087 | DK2: =IF(ISNUMBER(SowDate),SowDate-3+102,"") -> 46088 | DL2: =IF(ISNUMBER(SowDate),SowDate-3+103,"") -> 46089 | DM2: =IF(ISNUMBER(SowDate),SowDate-3+104,"") -> 46090 | DN2: =IF(ISNUMBER(SowDate),SowDate-3+105,"") -> 46091 | DO2: =IF(ISNUMBER(SowDate),SowDate-3+106,"") -> 46092 | DP2: =IF(ISNUMBER(SowDate),SowDate-3+107,"") -> 46093 | DQ2: =IF(ISNUMBER(SowDate),SowDate-3+108,"") -> 46094 | DR2: =IF(ISNUMBER(SowDate),SowDate-3+109,"") -> 46095 | DS2: =IF(ISNUMBER(SowDate),SowDate-3+110,"") -> 46096 | DT2: =IF(ISNUMBER(SowDate),SowDate-3+111,"") -> 46097 | DU2: =IF(ISNUMBER(SowDate),SowDate-3+112,"") -> 46098 | DV2: =IF(ISNUMBER(SowDate),SowDate-3+113,"") -> 46099 | DW2: =IF(ISNUMBER(SowDate),SowDate-3+114,"") -> 46100 | DX2: =IF(ISNUMBER(SowDate),SowDate-3+115,"") -> 46101 | DY2: =IF(ISNUMBER(SowDate),SowDate-3+116,"") -> 46102 | DZ2: =IF(ISNUMBER(SowDate),SowDate-3+117,"") -> 46103 | EA2: =IF(ISNUMBER(SowDate),SowDate-3+118,"") -> 46104 | EB2: =IF(ISNUMBER(SowDate),SowDate-3+119,"") -> 46105 | EC2: =IF(ISNUMBER(SowDate),SowDate-3+120,"") -> 46106 | ED2: =IF(ISNUMBER(SowDate),SowDate-3+121,"") -> 46107 | EE2: =IF(ISNUMBER(SowDate),SowDate-3+122,"") -> 46108 | EF2: =IF(ISNUMBER(SowDate),SowDate-3+123,"") -> 46109 | EG2: =IF(ISNUMBER(SowDate),SowDate-3+124,"") -> 46110 | EH2: =IF(ISNUMBER(SowDate),SowDate-3+125,"") -> 46111 | EI2: =IF(ISNUMBER(SowDate),SowDate-3+126,"") -> 46112 | EJ2: =IF(ISNUMBER(SowDate),SowDate-3+127,"") -> 46113 | EK2: =IF(ISNUMBER(SowDate),SowDate-3+128,"") -> 46114 | EL2: =IF(ISNUMBER(SowDate),SowDate-3+129,"") -> 46115 | EM2: =IF(ISNUMBER(SowDate),SowDate-3+130,"") -> 46116 | EN2: =IF(ISNUMBER(SowDate),SowDate-3+131,"") -> 46117 | EO2: =IF(ISNUMBER(SowDate),SowDate-3+132,"") -> 46118 | EP2: =IF(ISNUMBER(SowDate),SowDate-3+133,"") -> 46119 | EQ2: =IF(ISNUMBER(SowDate),SowDate-3+134,"") -> 46120 | ER2: =IF(ISNUMBER(SowDate),SowDate-3+135,"") -> 46121 | ES2: =IF(ISNUMBER(SowDate),SowDate-3+136,"") -> 46122 | ET2: =IF(ISNUMBER(SowDate),SowDate-3+137,"") -> 46123 | EU2: =IF(ISNUMBER(SowDate),SowDate-3+138,"") -> 46124 | EV2: =IF(ISNUMBER(SowDate),SowDate-3+139,"") -> 46125 | EW2: =IF(ISNUMBER(SowDate),SowDate-3+140,"") -> 46126 | EX2: =IF(ISNUMBER(SowDate),SowDate-3+141,"") -> 46127 | EY2: =IF(ISNUMBER(SowDate),SowDate-3+142,"") -> 46128 | EZ2: =IF(ISNUMBER(SowDate),SowDate-3+143,"") -> 46129 | FA2: =IF(ISNUMBER(SowDate),SowDate-3+144,"") -> 46130 | FB2: =IF(ISNUMBER(SowDate),SowDate-3+145,"") -> 46131 | FC2: =IF(ISNUMBER(SowDate),SowDate-3+146,"") -> 46132 | FD2: =IF(ISNUMBER(SowDate),SowDate-3+147,"") -> 46133 | FE2: =IF(ISNUMBER(SowDate),SowDate-3+148,"") -> 46134 | FF2: =IF(ISNUMBER(SowDate),SowDate-3+149,"") -> 46135 | FG2: =IF(ISNUMBER(SowDate),SowDate-3+150,"") -> 46136 | FH2: =IF(ISNUMBER(SowDate),SowDate-3+151,"") -> 46137 | FI2: =IF(ISNUMBER(SowDate),SowDate-3+152,"") -> 46138 | FJ2: =IF(ISNUMBER(SowDate),SowDate-3+153,"") -> 46139 | FK2: =IF(ISNUMBER(SowDate),SowDate-3+154,"") -> 46140 | FL2: =IF(ISNUMBER(SowDate),SowDate-3+155,"") -> 46141 | FM2: =IF(ISNUMBER(SowDate),SowDate-3+156,"") -> 46142 | FN2: =IF(ISNUMBER(SowDate),SowDate-3+157,"") -> 46143 | FO2: =IF(ISNUMBER(SowDate),SowDate-3+158,"") -> 46144 | FP2: =IF(ISNUMBER(SowDate),SowDate-3+159,"") -> 46145 | FQ2: =IF(ISNUMBER(SowDate),SowDate-3+160,"") -> 46146 | FR2: =IF(ISNUMBER(SowDate),SowDate-3+161,"") -> 46147 | FS2: =IF(ISNUMBER(SowDate),SowDate-3+162,"") -> 46148 | FT2: =IF(ISNUMBER(SowDate),SowDate-3+163,"") -> 46149 | FU2: =IF(ISNUMBER(SowDate),SowDate-3+164,"") -> 46150 | FV2: =IF(ISNUMBER(SowDate),SowDate-3+165,"") -> 46151 | FW2: =IF(ISNUMBER(SowDate),SowDate-3+166,"") -> 46152 | FX2: =IF(ISNUMBER(SowDate),SowDate-3+167,"") -> 46153 | FY2: =IF(ISNUMBER(SowDate),SowDate-3+168,"") -> 46154 | FZ2: =IF(ISNUMBER(SowDate),SowDate-3+169,"") -> 46155 | GA2: =IF(ISNUMBER(SowDate),SowDate-3+170,"") -> 46156 | GB2: =IF(ISNUMBER(SowDate),SowDate-3+171,"") -> 46157 | GC2: =IF(ISNUMBER(SowDate),SowDate-3+172,"") -> 46158 | GD2: =IF(ISNUMBER(SowDate),SowDate-3+173,"") -> 46159 | GE2: =IF(ISNUMBER(SowDate),SowDate-3+174,"") -> 46160
A3: Event | B3: ঘটনা | C3: Plot | D3: Planned start | E3: Planned end | F3: Actual start | G3: Actual end | H3: Status | I3: Delay (days) | J3: Used start | K3: Used end | L3: next | M3: =IF(M2="","",TEXT(M2,"mmm")) -> Nov | N3: =IF(N2="","",TEXT(N2,"mmm")) -> Nov | O3: =IF(O2="","",TEXT(O2,"mmm")) -> Nov | P3: =IF(P2="","",TEXT(P2,"mmm")) -> Nov | Q3: =IF(Q2="","",TEXT(Q2,"mmm")) -> Nov | R3: =IF(R2="","",TEXT(R2,"mmm")) -> Nov | S3: =IF(S2="","",TEXT(S2,"mmm")) -> Dec | T3: =IF(T2="","",TEXT(T2,"mmm")) -> Dec | ... GE3: =IF(GE2="","",TEXT(GE2,"mmm")) -> May
A4: 3F4D+MD plot
A5: Seed wetting | B5: বীজ ভেজানো | C5: 3F4D+MD | D5: =IF(ISNUMBER(1_Settings!C26),1_Settings!C26,"") -> 45986 | E5: =IF(D5="","",D5) -> 45986 | F5: =IF(_xlfn.MINIFS(2_Daily_input!$D$1:$FQ$1,2_Daily_input!$D$71:$FQ$71,"Seed wetting")+_xlfn.MINIFS(2_Daily_input!$D$1:$FQ$1,2_Daily_input!$D$72:$FQ$72,"Seed wetting")=0,"",IF(_xlfn.MINIFS(2_Daily_input!$D$1:$FQ$1,2_Daily_input!$D$71:$FQ$71,"Seed wetting")=0,_xlfn.MINIFS(2_Daily_input!$D$1:$FQ$1,2_Daily_input!$D$72:$FQ$72,"Seed wetting"),IF(_xlfn.MINIFS(2_Daily_input!$D$1:$FQ$1,2_Daily_input!$D$72:$FQ$72,"Seed wetting")=0,_xlfn.MINIFS(2_Daily_input!$D$1:$FQ$1,2_Daily_input!$D$71:$FQ$71,"Seed wetting"),MIN(_xlfn.MINIFS(2_Daily_input!$D$1:$FQ$1,2_Daily_input!$D$71:$FQ$71,"Seed wetting"),_xlfn.MINIFS(2_Daily_input!$D$1:$FQ$1,2_Daily_input!$D$72:$FQ$72,"Seed wetting"))))) -> 45986 | G5: ="" | H5: =IF(D5="","no plan",IF(F5<>"",IF(F5-D5>=2,"LATE","OK"),IF(TODAY()>D5+2,"OVERDUE","upcoming"))) -> OK | I5: =IF(AND(D5<>"",F5<>""),F5-D5,"") -> 0 | J5: =IF(F5<>"",F5,D5) -> 45986 | K5: =IF(G5<>"",G5,IF(AND(F5<>"",E5=D5),F5,E5)) -> 45986 | L5: =IF(AND(D5<>"",F5="",D5>=TODAY()),D5+ROW()/1000,"") | M5: =IF(OR(M$2="",$D5=""),"",IF(IF(ISNUMBER($F5),AND(M$2>=$F5,M$2<=IF(ISNUMBER($G5),$G5,$F5+$E5-$D5)),FALSE()),2,IF(AND(M$2>=$D5,M$2<=$E5),1,""))) -> 2 | N5: =IF(OR(N$2="",$D5=""),"",IF(IF(ISNUMBER($F5),AND(N$2>=$F5,N$2<=IF(ISNUMBER($G5),$G5,$F5+$E5-$D5)),FALSE()),2,IF(AND(N$2>=$D5,N$2<=$E5),1,""))) | O5: =IF(OR(O$2="",$D5=""),"",IF(IF(ISNUMBER($F5),AND(O$2>=$F5,O$2<=IF(ISNUMBER($G5),$G5,$F5+$E5-$D5)),FALSE()),2,IF(AND(O$2>=$D5,O$2<=$E5),1,""))) | P5: =IF(OR(P$2="",$D5=""),"",IF(IF(ISNUMBER($F5),AND(P$2>=$F5,P$2<=IF(ISNUMBER($G5),$G5,$F5+$E5-$D5)),FALSE()),2,IF(AND(P$2>=$D5,P$2<=$E5),1,""))) | Q5: =IF(OR(Q$2="",$D5=""),"",IF(IF(ISNUMBER($F5),AND(Q$2>=$F5,Q$2<=IF(ISNUMBER($G5),$G5,$F5+$E5-$D5)),FALSE()),2,IF(AND(Q$2>=$D5,Q$2<=$E5),1,""))) | R5: =IF(OR(R$2="",$D5=""),"",IF(IF(ISNUMBER($F5),AND(R$2>=$F5,R$2<=IF(ISNUMBER($G5),$G5,$F5+$E5-$D5)),FALSE()),2,IF(AND(R$2>=$D5,R$2<=$E5),1,""))) | S5: =IF(OR(S$2="",$D5=""),"",IF(IF(ISNUMBER($F5),AND(S$2>=$F5,S$2<=IF(ISNUMBER($G5),$G5,$F5+$E5-$D5)),FALSE()),2,IF(AND(S$2>=$D5,S$2<=$E5),1,""))) | T5: =IF(OR(T$2="",$D5=""),"",IF(IF(ISNUMBER($F5),AND(T$2>=$F5,T$2<=IF(ISNUMBER($G5),$G5,$F5+$E5-$D5)),FALSE()),2,IF(AND(T$2>=$D5,T$2<=$E5),1,""))) | ... GE5: =IF(OR(GE$2="",$D5=""),"",IF(IF(ISNUMBER($F5),AND(GE$2>=$F5,GE$2<=IF(ISNUMBER($G5),$G5,$F5+$E5-$D5)),FALSE()),2,IF(AND(GE$2>=$D5,GE$2<=$E5),1,"")))
A6: Sowing | B6: বপন | C6: 3F4D+MD | D6: =IF(ISNUMBER(SowDate),SowDate,"") -> 45989 | E6: =IF(D6="","",D6) -> 45989 | F6: =IF(_xlfn.MINIFS(2_Daily_input!$D$1:$FQ$1,2_Daily_input!$D$71:$FQ$71,"Sowing")+_xlfn.MINIFS(2_Daily_input!$D$1:$FQ$1,2_Daily_input!$D$72:$FQ$72,"Sowing")=0,"",IF(_xlfn.MINIFS(2_Daily_input!$D$1:$FQ$1,2_Daily_input!$D$71:$FQ$71,"Sowing")=0,_xlfn.MINIFS(2_Daily_input!$D$1:$FQ$1,2_Daily_input!$D$72:$FQ$72,"Sowing"),IF(_xlfn.MINIFS(2_Daily_input!$D$1:$FQ$1,2_Daily_input!$D$72:$FQ$72,"Sowing")=0,_xlfn.MINIFS(2_Daily_input!$D$1:$FQ$1,2_Daily_input!$D$71:$FQ$71,"Sowing"),MIN(_xlfn.MINIFS(2_Daily_input!$D$1:$FQ$1,2_Daily_input!$D$71:$FQ$71,"Sowing"),_xlfn.MINIFS(2_Daily_input!$D$1:$FQ$1,2_Daily_input!$D$72:$FQ$72,"Sowing"))))) -> 45989 | G6: ="" | H6: =IF(D6="","no plan",IF(F6<>"",IF(F6-D6>=2,"LATE","OK"),IF(TODAY()>D6+2,"OVERDUE","upcoming"))) -> OK | I6: =IF(AND(D6<>"",F6<>""),F6-D6,"") -> 0 | J6: =IF(F6<>"",F6,D6) -> 45989 | K6: =IF(G6<>"",G6,IF(AND(F6<>"",E6=D6),F6,E6)) -> 45989 | L6: =IF(AND(D6<>"",F6="",D6>=TODAY()),D6+ROW()/1000,"") | M6: =IF(OR(M$2="",$D6=""),"",IF(IF(ISNUMBER($F6),AND(M$2>=$F6,M$2<=IF(ISNUMBER($G6),$G6,$F6+$E6-$D6)),FALSE()),2,IF(AND(M$2>=$D6,M$2<=$E6),1,""))) | N6: =IF(OR(N$2="",$D6=""),"",IF(IF(ISNUMBER($F6),AND(N$2>=$F6,N$2<=IF(ISNUMBER($G6),$G6,$F6+$E6-$D6)),FALSE()),2,IF(AND(N$2>=$D6,N$2<=$E6),1,""))) | O6: =IF(OR(O$2="",$D6=""),"",IF(IF(ISNUMBER($F6),AND(O$2>=$F6,O$2<=IF(ISNUMBER($G6),$G6,$F6+$E6-$D6)),FALSE()),2,IF(AND(O$2>=$D6,O$2<=$E6),1,""))) | P6: =IF(OR(P$2="",$D6=""),"",IF(IF(ISNUMBER($F6),AND(P$2>=$F6,P$2<=IF(ISNUMBER($G6),$G6,$F6+$E6-$D6)),FALSE()),2,IF(AND(P$2>=$D6,P$2<=$E6),1,""))) -> 2 | Q6: =IF(OR(Q$2="",$D6=""),"",IF(IF(ISNUMBER($F6),AND(Q$2>=$F6,Q$2<=IF(ISNUMBER($G6),$G6,$F6+$E6-$D6)),FALSE()),2,IF(AND(Q$2>=$D6,Q$2<=$E6),1,""))) | R6: =IF(OR(R$2="",$D6=""),"",IF(IF(ISNUMBER($F6),AND(R$2>=$F6,R$2<=IF(ISNUMBER($G6),$G6,$F6+$E6-$D6)),FALSE()),2,IF(AND(R$2>=$D6,R$2<=$E6),1,""))) | S6: =IF(OR(S$2="",$D6=""),"",IF(IF(ISNUMBER($F6),AND(S$2>=$F6,S$2<=IF(ISNUMBER($G6),$G6,$F6+$E6-$D6)),FALSE()),2,IF(AND(S$2>=$D6,S$2<=$E6),1,""))) | T6: =IF(OR(T$2="",$D6=""),"",IF(IF(ISNUMBER($F6),AND(T$2>=$F6,T$2<=IF(ISNUMBER($G6),$G6,$F6+$E6-$D6)),FALSE()),2,IF(AND(T$2>=$D6,T$2<=$E6),1,""))) | ... GE6: =IF(OR(GE$2="",$D6=""),"",IF(IF(ISNUMBER($F6),AND(GE$2>=$F6,GE$2<=IF(ISNUMBER($G6),$G6,$F6+$E6-$D6)),FALSE()),2,IF(AND(GE$2>=$D6,GE$2<=$E6),1,"")))
